Workbook
Name adicional_noturno: Indiretos!$H$14
Name adm_central: 'Adm Central'!$L$79
Name administração_local: Indiretos!$V$67
Name ajuste_HE_mdo_direta: BDI!$M$10
Name alojamentos: Indiretos!$Q$200
Name alojamentos_valor: Indiretos!$P$200
Name bdi: BDI!$H$39
Name canteiro_de_obras: Indiretos!$Q$234
Name canteiro_de_obras_valor: Indiretos!$P$234
Name Consultorias: Indiretos!$V$101
Name Consultorias_Valor: Indiretos!$V$101
Name controle_técnológico: Indiretos!$Q$499
Name controle_técnológico_valor: Indiretos!$P$499
Name custo_direto: BDI!$J$8
Name custo_direto_com_desconto_eventual: BDI!$J$8
Name custo_indireto: BDI!$J$14
Name data_base_da_obra: BDI!$J$6
Name desoneração: BDI!$H$32
Name despesas_administrativas: Indiretos!$Q$309
Name despesas_administrativas_valor: Indiretos!$P$309
Name despesas_indiretas: BDI!$J$26
Name dias_úteis_trabalhados: Indiretos!$K$11
Name dissídio_coletivo: Indiretos!$E$15
Name domingos_trabalhados: Indiretos!$K$13
Name efetivo_médio_dia: Indiretos!$AW$29
Name efetivo_médio_mes: BDI!$L$20
Name encargos_mensalista: Indiretos!$N$16
Name epi: Indiretos!$Q$455
Name epi_valor: Indiretos!$P$455
Name equipamentos: Indiretos!$Q$358
Name equipamentos_valor: Indiretos!$P$358
Name faturamento_anual: 'Taxa de Comercialização'!$G$9
Name ferramentas: Indiretos!$Q$419
Name ferramentas_valor: Indiretos!$P$419
Name hora_extra_dias_úteis: '[6]MDO - Indiretos'!$K$9
Name hora_extra_dias_úteis: Indiretos!$H$11
Name hora_extra_domingos: '[6]MDO - Indiretos'!$K$11
Name hora_extra_domingos: Indiretos!$H$13
Name hora_extra_mdo_direta: '[6]MDO - Indiretos'!$AH$108
Name hora_extra_mdo_direta: Indiretos!$AV$108
Name hora_extra_mdo_indireta: '[6]MDO - Indiretos'!$AH$107
Name hora_extra_mdo_indireta: Indiretos!$AV$107
Name hora_extra_sábados: '[6]MDO - Indiretos'!$K$10
Name hora_extra_sábados: Indiretos!$H$12
Name incidência_do_dissídio: '[6]MDO - Indiretos'!$K$13
Name incidência_do_dissídio: Indiretos!$H$15
Name ISS: [6]BDI!$H$37
Name ISS: BDI!$H$33
Name juros_medio: '[6]Despesas Financeiras'!$D$16
Name juros_medio: 'Despesas Financeiras'!$D$17
Name lucro_liquido: [6]BDI!$H$40
Name lucro_liquido: BDI!$H$38
Name lucro_liquido_valor: [6]BDI!$J$40
Name lucro_liquido_valor: BDI!$J$38
Name materiais: BDI!$J$9
Name mdo: BDI!$J$10
Name mdo_direta_alojada: '[6]Refeições Transporte Alojamento'!$G$10
Name mdo_direta_alojada: Indiretos!$R$115
Name mdo_direta_não_alojada: Indiretos!$S$115
Name mdo_indireta: Indiretos!$V$107

Sheet BDI
D2: Bonificação e Despesas Indiretas
F3: FC ENGENHARIA E CONSULTORIA LTDA
F4: julho/19 - Com desoneração da Folha de Pagamento
C6: ARQUIVO: | D6: =MID(CELL("filename"),SEARCH("[",CELL("filename"))+1,SEARCH("]",CELL("filename"))-SEARCH("[",CELL("filename"))-1) -> BDI_747.xlsx | G6: =Indiretos!E12&" meses" -> 8 meses | H6: =108.68+1074.09+1013.97+855.37+1002.53+904.62+904.62+904.62+421.75+904.62+110.96+110.96 -> 8316.79 | I6: Data: | J6: =TODAY() -> 46093
C8: CD | D8: Custo Direto | I8: =custo_direto/$H$6 -> 685.234 | J8: =materiais+J13 -> 5698947.3
B9: CD-01 | C9: CD-01 | D9: Materiais | H9: =materiais/custo_direto -> 0.57301332 | I9: =J9/$H$6 -> 392.64821 | J9: 3265572.7
B10: CD-02 | C10: CD-02 | D10: MDO Direta | I10: =J10/$H$6 -> 277.56353 | J10: 2308437.6 | L10: H.E. (reajuste) = | M10: =SUM(J11:J12)/mdo -> 0.054121877
B11: CD-02.1 | C11: CD-02.1 | D11: Horas Extras | H11: =J11/custo_direto -> 0 | J11: =hora_extra_mdo_direta -> 0
B12: CD-02.2 | C12: CD-02.2 | D12: Transferência + Ociosidade + Dissídio | H12: =J12/custo_direto -> 0.021922817 | J12: =transf_diss_ocio_mdo_direta -> 124936.98
B13: CD-03 | C13: CD-03 | D13: Total MDO Direta Reajustada | H13: =J13/custo_direto -> 0.42698668 | J13: =SUM(J10:J12) -> 2433374.6
B14: CI | C14: CI | D14: Custo Indireto | H14: =custo_indireto/custo_direto -> 0.10368564 | I14: =custo_indireto/$H$6 -> 71.048923 | J14: =SUM($J$18:$J$25) -> 590898.97
B15: CI-01.1 | C15: CI-01.1 | D15: Administração de obra | H15: =J15/custo_direto -> 0.036030046 | J15: =mdo_indireta_valor -> 205333.33
B16: CI-01.2 | C16: CI-01.2 | D16: Horas Extras | H16: =J16/custo_direto -> 0 | J16: =hora_extra_mdo_indireta -> 0 | O16: Despesas Indiretas Sem NF
B17: CI-01.3 | C17: CI-01.3 | D17: Transferência + Ociosidade + Dissídio | H17: =J17/custo_direto -> 0.0013511267 | J17: =transf_diss_ocio_mdo_indireta -> 7700
B18: CI-01 | C18: =HYPERLINK("#"&"'Indiretos'!D"&MATCH(B18,Indiretos!D:D,0),B18) -> CI-01 | D18: Administração de obra | H18: =J18/custo_direto -> 0.037381173 | I18: =J18/$H$6 -> 25.614851 | J18: =SUM(J15:J17) -> 213033.33 | L18: Efetivo mensal | O18: =H28 -> 0.0065 | P18: =O18*valor_de_venda1*$H$57 -> 27019.291
B19: CI-02 | C19: =HYPERLINK("#"&"'Indiretos'!D"&MATCH(B19,Indiretos!D:D,0),B19) -> CI-02 | D19: Refeições, Transportes e Estadias | H19: =J19/custo_direto -> 0.028788475 | I19: =J19/$H$6 -> 19.726842 | J19: =refeições_valor+transportes_valor+alojamentos_valor -> 164064 | L19: M.D.O Direta | M19: M.D.O Terceirizada | O19: =H29 -> 0.03 | P19: =O19*valor_de_venda1*$H$57 -> 124704.42
B20: CI-03 | C20: =HYPERLINK("#"&"'Indiretos'!D"&MATCH(B20,Indiretos!D:D,0),B20) -> CI-03 | D20: Canteiro de obras conservação e manutenção | H20: =J20/custo_direto -> 0.0063169562 | I20: =J20/$H$6 -> 4.3285931 | J20: =canteiro_de_obras_valor -> 36000 | L20: 40 | M20: 40 | O20: =H30 -> 0.012 | P20: =O20*valor_de_venda1*$H$57 -> 49881.768
B21: CI-04 | C21: =HYPERLINK("#"&"'Indiretos'!D"&MATCH(B21,Indiretos!D:D,0),B21) -> CI-04 | D21: Despesas Administrativas da obra | H21: =J21/custo_direto -> 0 | I21: =J21/$H$6 -> 0 | J21: =despesas_administrativas_valor -> 0 | L21: Supervisão e Apoio | O21: =H31 -> 0.0108 | P21: =O21*valor_de_venda1*$H$57 -> 44893.591
B22: CI-05 | C22: =HYPERLINK("#"&"'Indiretos'!D"&MATCH(B22,Indiretos!D:D,0),B22) -> CI-05 | D22: Máquinas, Ferramentas e Equipamentos | H22: =J22/custo_direto -> 0.0182278 | I22: =J22/$H$6 -> 12.490308 | J22: =ferramentas_valor+equipamentos_valor -> 103879.27 | L22: 3 | O22: =H32 -> 0 | P22: =O22*valor_de_venda1*$H$57 -> 0
B23: CI-06 | C23: =HYPERLINK("#"&"'Indiretos'!D"&MATCH(B23,Indiretos!D:D,0),B23) -> CI-06 | D23: Saúde e segurança do trabalho - ASO, EPI's e EPC's, conforme NR-6 | H23: =J23/custo_direto -> 0.012971232 | I23: =J23/$H$6 -> 8.8883291 | J23: =epi_valor+treinamentos_valor -> 73922.367 | L23: Coordenação | O23: =H33 -> 0.05 | P23: =O23*valor_de_venda1*$H$57 -> 207840.7
A24: S | B24: CI-07 | C24: =HYPERLINK("#"&"'Indiretos'!D"&MATCH(B24,Indiretos!D:D,0),B24) -> CI-07 | D24: Projetos complementares e controle tecnológico | H24: =J24/custo_direto -> 0 | J24: =mobilização_terceiros_valor+serviços_técnicos_valor+controle_técnológico_valor+projetos_valor -> 0 | L24: 1
B25: CI-08 | C25: =HYPERLINK("#"&"'Despesas Financeiras'!D"&MATCH(B25,'Despesas Financeiras'!B:B,0),B25) -> CI-08 | D25: Custo Financeiros, seguros e garantia ( art.618 cód. Civil ) | H25: =J25/custo_direto -> 5.2641301e-11 | J25: =montante_do_juros -> 0.0003
B26: DI | C26: DI | D26: Despesas Indiretas sem FD | H26: =despesas_indiretas/custo_direto -> 0.19759873 | I26: =despesas_indiretas/$H$6 -> 135.40137 | J26: =SUM($J$27:$J$39) -> 1126104.8 | L26: IMPOSTOS | O26: IMPOSTOS FD
A27: S | B27: DI-01 | C27: DI-01 | D27: Taxa de Administração Central | H27: =adm_central -> 0.04 | J27: =H27*$J$45 -> 166272.56
B28: DI-02 | C28: DI-02 | D28: PIS - Programa de Integração Social | H28: =0.65% -> 0.0065 | J28: =H28*$J$45 -> 27019.291 | L28: =H28 -> 0.0065 | M28: =L28*$J$45 -> 27019.291 | O28: =H28 -> 0.0065 | P28: =O28*valor_de_venda2 -> 48750
B29: DI-03 | C29: DI-03 | D29: COFINS - Financiamento da Seguridade Social | G29: =SUM(J28:J33) -> 454339.77 | H29: =3% -> 0.03 | J29: =H29*$J$45 -> 124704.42 | L29: =H29 -> 0.03 | M29: =L29*$J$45 -> 124704.42 | O29: =H29 -> 0.03 | P29: =O29*valor_de_venda2 -> 225000
B30: DI-04 | C30: DI-04 | D30: IRPJ - Imposto de Renda de Pessoa Jurídica | H30: =1.2% -> 0.012 | J30: =H30*$J$45 -> 49881.768 | L30: =H30 -> 0.012 | M30: =L30*$J$45 -> 49881.768 | O30: =H30 -> 0.012 | P30: =O30*valor_de_venda2 -> 90000
B31: DI-05 | C31: DI-05 | D31: CSLL - Contribuição Social do Lucro Líquido | H31: =1.08% -> 0.0108 | J31: =H31*$J$45 -> 44893.591 | L31: =H31 -> 0.0108 | M31: =L31*$J$45 -> 44893.591 | O31: =H31 -> 0.0108 | P31: =O31*valor_de_venda2 -> 81000
B32: DI-06 | C32: DI-06 | D32: CPRB - Contribuição Previdenciária Receita Bruta ( Lei nº 12.546/11 ) | H32: 0 | J32: =H32*$J$45 -> 0 | L32: =H32 -> 0 | M32: =L32*$J$45 -> 0 | O32: =H32 -> 0 | P32: =O32*valor_de_venda2 -> 0
B33: DI-07 | C33: DI-07 | D33: ISS Municipal* | F33: Dedução ISS = | G33: 0 | H33: 0.05 | J33: =H33*$J$45*(1-$G$33) -> 207840.7 | L33: =H33 -> 0.05 | M33: =L33*$J$45 -> 207840.7 | O33: =H33 -> 0.05 | P33: =O33*valor_de_venda2 -> 375000
B34: DI-08 | C34: DI-08 | D34: Taxa de risco, Imprevistos e pós obra. | H34: 0.05 | J34: =$H$34*$J$45 -> 207840.7 | L34: Impostos
B35: DI-09 | C35: DI-09 | D35: Seguro de responsabilidade civil e risco de engenharia | H35: 0 | J35: =$H$35*$J$45 -> 0 | L35: =SUM(L28:L33) -> 0.1093
B36: DI-09 | C36: DI-10 | D36: Comissionamento | H36: 0.007 | J36: =valor_de_venda1*H36 -> 29097.698 | L36: Atenção adotar 18,25% | M36: =(1/(1-L35)-100%) -> 0.12271247
B37: B | C37: B | D37: Bonificações
B38: B-01 | C38: B-01 | D38: Lucro Bruto Arbitrário | H38: 0.064605738 | J38: =lucro_liquido*$J$45 -> 268554.04
B39: B-02 | C39: B-02 | D39: BDI | H39: =SUM($H$34:$H$38)+SUM($H$27:$H$32)+ISS*(1-$G$33) -> 0.27090574
B40: B-01 | C40: B-04 | D40: Comissionamento líquido | J40: =(H36*valor_de_venda2) -> 52500
B41: B-01 | C41: B-05 | D41: Lucro Liquido | H41: =J41/valor_de_venda2 -> 0.064605738 | J41: =lucro_liquido*valor_de_venda2 -> 484543.03
B42: B-01 | C42: B-03 | D42: Lucro Mensal liquido | H42: =lucro_liquido/meses_obra -> 0.0080757172 | J42: =J38/meses_obra -> 33569.255
C43: CD + CI = | D43: ABNT16.633/CEE-162 | J43: =custo_direto+custo_indireto-'F.D.'!H121-'Bdi CURVA ABC - MAT'!H210 -> 3030709.2 | K43: =J43/H6 -> 364.40853
...

Sheet Indiretos
F2: Mão de Obra Indireta | T2: Materiais = | U2: =materiais -> 3265572.7
F3: =BDI!F3 -> FC ENGENHARIA E CONSULTORIA LTDA | T3: Mão de Obra = | U3: =mdo+hora_extra_mdo_direta+transf_diss_ocio_mdo_direta -> 2433374.6
F4: =BDI!F4 -> julho/19 - Com desoneração da Folha de Pagamento | T4: Σ = | U4: =SUM(U2:U3) -> 5698947.3
D6: Obra: | E6: =nome_da_obra -> BDI_747.xlsx | T6: Data base: | U6: =data_base_da_obra -> 46093
Z7: Reincidência de Encargos sobre hora extra
D8: QUADRO 1 - | E8: MÃO DE OBRA | Z8: 13º salário | AA8: =1/12 -> 0.083333333 | AB8: (artigo 142, § 5º da CLT)
Z9: Férias | AA9: =(1+1/3)/12 -> 0.11111111 | AB9: (artigo 142, § 5º da CLT)
P10: % de presença de MDO para horas extras | S10: Parâmetros Mín ( NR-18 e NR-4 ) | U10: CLT | Z10: Aviso prévio | AA10: =7/30/12 -> 0.019444444 | AB10: (alíneas “a” e “b” do artigo 7º da Lei nº 605/49)
D11: Data de início = | E11: =TODAY()+20 -> 46113 | G11: Hora extra dias úteis = | H11: 0.6 | J11: D. úteis trabalhados/mês = | K11: 22 | M11: Hora Extra em dias úteis = | N11: 0 | P11: Em dias úteis diurno = | Q11: 0.05 | S11: média homem/mês = | T11: =efetivo_médio_mes+média_supervisão+média_coordenação -> 44 | U11: Contrato | Z11: FGTS | AA11: 0.08 | AB11: (súmula 63 do TST)
D12: Prazo de obra = | E12: 8 | F12: meses | G12: Hora extra sábados = | H12: 0.6 | J12: Sáb. trabalhados/mês = | K12: 0 | M12: Hora Extra em sábados = | N12: 0 | P12: Em sábados diurno = | Q12: 0 | S12: Qtd mín Bacia e mic = | T12: =IF($T$11/20<0,1,ROUNDUP(($T$11/20),0)) -> 3 | Z12: Multa FGTS | AA12: =0.4*0.08 -> 0.032 | AB12: (súmula 63 do TST)
D13: Eventual atraso = | E13: 0 | F13: meses | G13: Hora extra domingos = | H13: 1 | J13: Dom. trabalhados/mês = | K13: 0 | M13: Hora Extra em domingos = | N13: 0 | P13: Em domingos diurno = | Q13: 0 | S13: Qtd mín chuveiro = | T13: =IF($T$11/20<0,1,ROUNDUP(($T$11/10),0)) -> 5 | Z13: DSR | AA13: 0.16831683 | AB13: (alíneas “a” e “b” do artigo 7º da Lei nº 605/49),
D14: Meses da obra = | E14: 8 | F14: meses | G14: Adicional noturno = | H14: 0.2 | J14: D. úteis trab. noturno/mês = | K14: 0 | M14: Hora Extra adic.noturno = | N14: 0 | P14: Em dias úteis noturno = | Q14: 0 | S14: Necessário Ambulatorio = | T14: NÃO | AA14: =SUM(AA8:AA13) -> 0.49420572
D15: Dissídio coletivo = | E15: 0.05 | F15: 46143 | G15: Incidência do dissídio = | H15: =IF((E11-F15)>0,0,IF((-(F15-E16)/30)<0,0,ROUNDDOWN((-(F15-E16)/30),0))) -> 7 | J15: Sáb. trab. noturno/mês = | K15: 0 | M15: Ociosidade por dia (h) = | N15: 0 | P15: Em sábados noturno = | Q15: 0 | S15: Necessário Tec. Seg. = | T15: SIM | U15: full time
D16: Data de fim = | E16: =EDATE(E11,+meses_obra) -> 46357 | G16: % de MDO Local (h) = | H16: 1 | J16: Dom trab. noturno/mês = | K16: 0 | M16: Encargos Sociais = | N16: 1.1268768 | P16: Em domingos noturno = | Q16: 0 | S16: Necessário Eng. Seg. = | T16: NÃO | U16: *part time
S18: Valor base conforme Convenção coletiva de trabalho ( CCT ) | AO18: CONSIDERADO HORA EXTRA+20%
D19: CD-03 | E19: MÃO DE OBRA DIRETA | I19: MODALIDADE | J19: QUANTIDADE | K19: TX. TRANSF | L19: ΔT EM OBRA | M19: UN | N19: BONUS MENSAL | O19: 13º + FÉRIAS PARA PJ | P19: VALOR HORA (ajustada) | Q19: QTD DE H.E. PREVISTA | S19: VALORES TOTAIS H.E. | U19: Total c/ HE | V19: =$U$21/meses_obra -> 372579.91 | Z19: Valor hora | AE19: Qtd de hora extra | AH19: Qtd adicional noturno | AL19: Valores unitários de Hora Extra | AO19: Unit. Hora Extra + Adc. noturno | AV19: MENSAL | AX19: TOTAL
Q20: =$H$11 -> 0.6 | R20: =hora_extra_domingos -> 1 | S20: =Q20 -> 0.6 | T20: =R20 -> 1 | AE20: dia útil | AF20: sáb | AG20: dom | AH20: dia útil | AI20: sáb | AJ20: dom | AL20: dia útil | AM20: sáb | AN20: dom | AO20: dia útil | AP20: sáb | AQ20: dom | AV20: Total s/ H.E. | AW20: Total c/ H.E. | AX20: Total s/ HE
D21: 01 | E21: Equipe - Mão de obra direta | O21: Proporcional | U21: =SUMIF(A:A,D21,U:U) -> 2980639.3 | Z21: com L.S. | AA21: Transf | AB21: Dissidio | AC21: Ossiosidade | AE21: HE d.útil | AF21: Qtd sáb | AG21: Qtd dom | AH21: HE d.útil | AI21: Qtd sáb | AJ21: Qtd dom | AL21: VH.d.útil | AM21: VH.sáb | AN21: VH.dom | AO21: VH.d.útil | AP21: VH.sáb | AQ21: VH.dom | AX21: =SUMIF(A:A,D21,AX:AX) -> 2980639.3
A22: 1 | D22: 1.01 | E22: Ajudante (MDO Base salarial Local) | H22: mês | I22: CLT | J22: =ROUND(((((mdo/(média_salarial_ponderada/220)/220)*0.5)/meses_obra)/(1+encargos_mensalista)),10)*percentual_de_mdo_local -> 35.832925 | L22: =meses_obra -> 8 | M22: =(9.39*220) -> 2065.8 | N22: 0 | O22: =IF(I22="CLT","N/A",(L22*(M22/12)*2)) -> N/A | P22: =AC22 -> 20.845121 | Q22: =AE22+AF22 -> 0 | R22: =AG22 -> 0 | S22: =Q22*AL22 -> 0 | T22: =R22*AN22 -> 0 | U22: =AW22*L22*J22 -> 1314617.3 | Z22: =IF(I22="CLT",(M22/220)*(1+encargos_mensalista),(M22/220)) -> 19.971373 | AA22: =Z22*(1+K22) -> 19.971373 | AB22: =AA22*(1+((incidência_do_dissídio/meses_obra)*dissídio_coletivo)) -> 20.845121 | AC22: =AB22*(1+(ociosidade_por_dia/9)) -> 20.845121 | AE22: =IF(I22="contrato",0,$N$11*$Q$11*$K$11) -> 0 | AF22: =IF(I22="contrato",0,$N$12*$Q$12*$K$12) -> 0 | AG22: =IF(I22="contrato",0,$N$13*$Q$13*$K$13) -> 0 | AH22: =IF(I22="contrato",0,$N$14*$Q$14*$K$14) -> 0 | AI22: =IF(I22="contrato",0,$N$14*$Q$15*$K$15) -> 0 | AJ22: =IF(I22="contrato",0,$N$14*$Q$16*$K$16) -> 0 | AL22: =IF(I22="contrato",0,ROUNDUP((M22/220)*(1+$AA$14)*(1+hora_extra_dias_úteis),2)) -> 22.45 | AM22: =IF(I22="contrato",0,ROUNDUP((M22/220)*(1+$AA$14)*(1+hora_extra_sábados),2)) -> 22.45 | AN22: =IF(I22="contrato",0,ROUNDUP((M22/220)*(1+$AA$14)*(1+hora_extra_domingos),2)) -> 28.07 | AO22: =IF(I22="contrato",0,ROUNDUP(AL22*(1+adicional_noturno),2)) -> 26.94 | AP22: =IF(I22="contrato",0,ROUNDUP(AM22*(1+adicional_noturno),2)) -> 26.94 | AQ22: =IF(I22="contrato",0,ROUNDUP(AN22*(1+adicional_noturno),2)) -> 33.69 | AV22: =IF(I22="CLT",IF(L22=0,0,P22*220+N22),(P22*220+N22+(O22/meses_obra))) -> 4585.9266 | AW22: =IF(I22="CLT",IF(L22=0,0,((P22*220)+(AE22*AL22)+(AF22*AM22)+(AG22*AN22)+(AH22*AO22)+(AI22*AP22)+(AJ22*AQ22)+N22)),AV22) -> 4585.9266 | AX22: =AV22*L22*J22 -> 1314617.3
A23: 1 | D23: 1.02 | E23: Oficiais (MDO Base salarial Local) | H23: mês | I23: CLT | J23: =ROUND(((((mdo/(média_salarial_ponderada/220)/220)*0.5)/meses_obra)/(1+encargos_mensalista)),10)*percentual_de_mdo_local -> 35.832925 | L23: =meses_obra -> 8 | M23: =(11.9*220) -> 2618 | N23: 0 | O23: =IF(I23="CLT","N/A",(L23*(M23/12)*2)) -> N/A | P23: =AC23 -> 26.417139 | Q23: =AE23+AF23 -> 0 | R23: =AG23 -> 0 | S23: =Q23*AL23 -> 0 | T23: =R23*AN23 -> 0 | U23: =AW23*L23*J23 -> 1666021.9 | Z23: =IF(I23="CLT",(M23/220)*(1+encargos_mensalista),(M23/220)) -> 25.309834 | AA23: =Z23*(1+K23) -> 25.309834 | AB23: =AA23*(1+((incidência_do_dissídio/meses_obra)*dissídio_coletivo)) -> 26.417139 | AC23: =AB23*(1+(ociosidade_por_dia/9)) -> 26.417139 | AE23: =IF(I23="contrato",0,$N$11*$Q$11*$K$11) -> 0 | AF23: =IF(I23="contrato",0,$N$12*$Q$12*$K$12) -> 0 | AG23: =IF(I23="contrato",0,$N$13*$Q$13*$K$13) -> 0 | AH23: =IF(I23="contrato",0,$N$14*$Q$14*$K$14) -> 0 | AI23: =IF(I23="contrato",0,$N$14*$Q$15*$K$15) -> 0 | AJ23: =IF(I23="contrato",0,$N$14*$Q$16*$K$16) -> 0 | AL23: =IF(I23="contrato",0,ROUNDUP((M23/220)*(1+$AA$14)*(1+hora_extra_dias_úteis),2)) -> 28.45 | AM23: =IF(I23="contrato",0,ROUNDUP((M23/220)*(1+$AA$14)*(1+hora_extra_sábados),2)) -> 28.45 | AN23: =IF(I23="contrato",0,ROUNDUP((M23/220)*(1+$AA$14)*(1+hora_extra_domingos),2)) -> 35.57 | AO23: =IF(I23="contrato",0,ROUNDUP(AL23*(1+adicional_noturno),2)) -> 34.14 | AP23: =IF(I23="contrato",0,ROUNDUP(AM23*(1+adicional_noturno),2)) -> 34.14 | AQ23: =IF(I23="contrato",0,ROUNDUP(AN23*(1+adicional_noturno),2)) -> 42.69 | AV23: =IF(I23="CLT",IF(L23=0,0,P23*220+N23),(P23*220+N23+(O23/meses_obra))) -> 5811.7707 | AW23: =IF(I23="CLT",IF(L23=0,0,((P23*220)+(AE23*AL23)+(AF23*AM23)+(AG23*AN23)+(AH23*AO23)+(AI23*AP23)+(AJ23*AQ23)+N23)),AV23) -> 5811.7707 | AX23: =AV23*L23*J23 -> 1666021.9
A24: 1 | D24: 1.03 | E24: Ajudante (Transf.-Base do município de Origem) | H24: mês | I24: CLT | J24: =ROUND(((((mdo/(média_salarial_ponderada/220)/220)*0.4)/meses_obra)/(1+encargos_mensalista)),10)*(1-percentual_de_mdo_local) -> 0 | L24: =meses_obra -> 8 | M24: =M22 -> 2065.8 | N24: 0 | O24: =IF(I24="CLT","N/A",(L24*(M24/12)*2)) -> N/A | P24: =AC24 -> 20.845121 | Q24: =AE24+AF24 -> 0 | R24: =AG24 -> 0 | S24: =Q24*AL24 -> 0 | T24: =R24*AN24 -> 0 | U24: =AW24*L24*J24 -> 0 | Z24: =IF(I24="CLT",(M24/220)*(1+encargos_mensalista),(M24/220)) -> 19.971373 | AA24: =Z24*(1+K24) -> 19.971373 | AB24: =AA24*(1+((incidência_do_dissídio/meses_obra)*dissídio_coletivo)) -> 20.845121 | AC24: =AB24*(1+(ociosidade_por_dia/9)) -> 20.845121 | AE24: =IF(I24="contrato",0,$N$11*$Q$11*$K$11) -> 0 | AF24: =IF(I24="contrato",0,$N$12*$Q$12*$K$12) -> 0 | AG24: =IF(I24="contrato",0,$N$13*$Q$13*$K$13) -> 0 | AH24: =IF(I24="contrato",0,$N$14*$Q$14*$K$14) -> 0 | AI24: =IF(I24="contrato",0,$N$14*$Q$15*$K$15) -> 0 | AJ24: =IF(I24="contrato",0,$N$14*$Q$16*$K$16) -> 0 | AL24: =IF(I24="contrato",0,ROUNDUP((M24/220)*(1+$AA$14)*(1+hora_extra_dias_úteis),2)) -> 22.45 | AM24: =IF(I24="contrato",0,ROUNDUP((M24/220)*(1+$AA$14)*(1+hora_extra_sábados),2)) -> 22.45 | AN24: =IF(I24="contrato",0,ROUNDUP((M24/220)*(1+$AA$14)*(1+hora_extra_domingos),2)) -> 28.07 | AO24: =IF(I24="contrato",0,ROUNDUP(AL24*(1+adicional_noturno),2)) -> 26.94 | AP24: =IF(I24="contrato",0,ROUNDUP(AM24*(1+adicional_noturno),2)) -> 26.94 | AQ24: =IF(I24="contrato",0,ROUNDUP(AN24*(1+adicional_noturno),2)) -> 33.69 | AV24: =IF(I24="CLT",IF(L24=0,0,P24*220+N24),(P24*220+N24+(O24/meses_obra))) -> 4585.9266 | AW24: =IF(I24="CLT",IF(L24=0,0,((P24*220)+(AE24*AL24)+(AF24*AM24)+(AG24*AN24)+(AH24*AO24)+(AI24*AP24)+(AJ24*AQ24)+N24)),AV24) -> 4585.9266 | AX24: =AV24*L24*J24 -> 0
A25: 1 | D25: 1.04 | E25: Oficiais (Transf.-Base do município de Origem) | H25: mês | I25: CLT | J25: =ROUND(((((mdo/(média_salarial_ponderada/220)/220)*0.6)/meses_obra)/(1+encargos_mensalista)),10)*(1-percentual_de_mdo_local) -> 0 | L25: =meses_obra -> 8 | M25: =M23 -> 2618 | N25: 0 | O25: =IF(I25="CLT","N/A",(L25*(M25/12)*2)) -> N/A | P25: =AC25 -> 26.417139 | Q25: =AE25+AF25 -> 0 | R25: =AG25 -> 0 | S25: =Q25*AL25 -> 0 | T25: =R25*AN25 -> 0 | U25: =AW25*L25*J25 -> 0 | Z25: =IF(I25="CLT",(M25/220)*(1+encargos_mensalista),(M25/220)) -> 25.309834 | AA25: =Z25*(1+K25) -> 25.309834 | AB25: =AA25*(1+((incidência_do_dissídio/meses_obra)*dissídio_coletivo)) -> 26.417139 | AC25: =AB25*(1+(ociosidade_por_dia/9)) -> 26.417139 | AE25: =IF(I25="contrato",0,$N$11*$Q$11*$K$11) -> 0 | AF25: =IF(I25="contrato",0,$N$12*$Q$12*$K$12) -> 0 | AG25: =IF(I25="contrato",0,$N$13*$Q$13*$K$13) -> 0 | AH25: =IF(I25="contrato",0,$N$14*$Q$14*$K$14) -> 0 | AI25: =IF(I25="contrato",0,$N$14*$Q$15*$K$15) -> 0 | AJ25: =IF(I25="contrato",0,$N$14*$Q$16*$K$16) -> 0 | AL25: =IF(I25="contrato",0,ROUNDUP((M25/220)*(1+$AA$14)*(1+hora_extra_dias_úteis),2)) -> 28.45 | AM25: =IF(I25="contrato",0,ROUNDUP((M25/220)*(1+$AA$14)*(1+hora_extra_sábados),2)) -> 28.45 | AN25: =IF(I25="contrato",0,ROUNDUP((M25/220)*(1+$AA$14)*(1+hora_extra_domingos),2)) -> 35.57 | AO25: =IF(I25="contrato",0,ROUNDUP(AL25*(1+adicional_noturno),2)) -> 34.14 | AP25: =IF(I25="contrato",0,ROUNDUP(AM25*(1+adicional_noturno),2)) -> 34.14 | AQ25: =IF(I25="contrato",0,ROUNDUP(AN25*(1+adicional_noturno),2)) -> 42.69 | AV25: =IF(I25="CLT",IF(L25=0,0,P25*220+N25),(P25*220+N25+(O25/meses_obra))) -> 5811.7707 | AW25: =IF(I25="CLT",IF(L25=0,0,((P25*220)+(AE25*AL25)+(AF25*AM25)+(AG25*AN25)+(AH25*AO25)+(AI25*AP25)+(AJ25*AQ25)+N25)),AV25) -> 5811.7707 | AX25: =AV25*L25*J25 -> 0
A26: 1 | D26: 1.05 | H26: mês | I26: CLT | L26: =meses_obra -> 8 | N26: 0 | O26: =IF(I26="CLT","N/A",(L26*(M26/12)*2)) -> N/A | P26: =AC26 -> 0 | Q26: =AE26+AF26 -> 0 | R26: =AG26 -> 0 | S26: =Q26*AL26 -> 0 | T26: =R26*AN26 -> 0 | U26: =AW26*L26*J26 -> 0 | Z26: =IF(I26="CLT",(M26/220)*(1+encargos_mensalista),(M26/220)) -> 0 | AA26: =Z26*(1+K26) -> 0 | AB26: =AA26*(1+((incidência_do_dissídio/meses_obra)*dissídio_coletivo)) -> 0 | AC26: =AB26*(1+(ociosidade_por_dia/9)) -> 0 | AE26: =IF(I26="contrato",0,$N$11*$Q$11*$K$11) -> 0 | AF26: =IF(I26="contrato",0,$N$12*$Q$12*$K$12) -> 0 | AG26: =IF(I26="contrato",0,$N$13*$Q$13*$K$13) -> 0 | AH26: =IF(I26="contrato",0,$N$14*$Q$14*$K$14) -> 0 | AI26: =IF(I26="contrato",0,$N$14*$Q$15*$K$15) -> 0 | AJ26: =IF(I26="contrato",0,$N$14*$Q$16*$K$16) -> 0 | AL26: =IF(I26="contrato",0,ROUNDUP((M26/220)*(1+$AA$14)*(1+hora_extra_dias_úteis),2)) -> 0 | AM26: =IF(I26="contrato",0,ROUNDUP((M26/220)*(1+$AA$14)*(1+hora_extra_sábados),2)) -> 0 | AN26: =IF(I26="contrato",0,ROUNDUP((M26/220)*(1+$AA$14)*(1+hora_extra_domingos),2)) -> 0 | AO26: =IF(I26="contrato",0,ROUNDUP(AL26*(1+adicional_noturno),2)) -> 0 | AP26: =IF(I26="contrato",0,ROUNDUP(AM26*(1+adicional_noturno),2)) -> 0 | AQ26: =IF(I26="contrato",0,ROUNDUP(AN26*(1+adicional_noturno),2)) -> 0 | AV26: =IF(I26="CLT",IF(L26=0,0,P26*220+N26),(P26*220+N26+(O26/meses_obra))) -> 0 | AW26: =IF(I26="CLT",IF(L26=0,0,((P26*220)+(AE26*AL26)+(AF26*AM26)+(AG26*AN26)+(AH26*AO26)+(AI26*AP26)+(AJ26*AQ26)+N26)),AV26) -> 0 | AX26: =AV26*L26*J26 -> 0
A28: D | I28: Salario base (mês) média ponderada = | J28: 1893.1 | L28: média ponderada = | M28: =AVERAGE(M22:M25) -> 2341.9
D30: CI-01 | E30: ADMINISTRAÇÃO DA OBRA | I30: MODALIDADE | J30: QUANTIDADE | K30: TX. TRANSF | L30: ΔT EM OBRA | M30: SALÁRIO | N30: BONUS MENSAL | O30: 13º + FÉRIAS | P30: VALOR HORA | Q30: QTD DE H.E. PREVISTA | S30: VALORES TOTAIS H.E. | U30: Total c/ HE | V30: =$U$32/meses_obra -> 26629.167
Q31: =$H$11 -> 0.6 | R31: =hora_extra_domingos -> 1 | S31: =Q31 -> 0.6 | T31: =R31 -> 1
E32: TOTAL Administração da obra | U32: =SUMIF(A:A,"S",U:U) -> 213033.33 | Z32: Valor hora | AE32: Qtd de hora extra | AH32: Qtd adicional noturno | AL32: Valores unitários de Hora Extra | AO32: Unit. Hora Extra + Adc. noturno | AS32: Categoria | AV32: MENSAL | AX32: TOTAL
AE33: dia útil | AF33: sáb | AG33: dom | AH33: dia útil | AI33: sáb | AJ33: dom | AL33: =AE33 -> dia útil | AM33: =AF33 -> sáb | AN33: =AG33 -> dom | AO33: =AH33 -> dia útil | AP33: =AI33 -> sáb | AQ33: =AJ33 -> dom | AS33: Supervisão e apoio | AT33: Coordenação | AV33: Total s/ H.E. | AW33: Total c/ H.E. | AX33: Total s/ HE
A34: S | D34: 02 | E34: Equipe de Engenharia local | O34: Proporcional | U34: =SUMIF(A:A,D34,U:U) -> 213033.33 | Z34: com L.S. | AA34: Transf | AB34: Dissidio | AC34: Ossiosidade | AE34: HE d.útil | AF34: Qtd sáb | AG34: Qtd dom | AH34: HE d.útil | AI34: Qtd sáb | AJ34: Qtd dom | AL34: VH.d.útil | AM34: VH.sáb | AN34: VH.dom | AO34: VH.d.útil | AP34: VH.sáb | AQ34: VH.dom | AX34: =SUMIF(A:A,D34,AX:AX) -> 213033.33
A35: 2 | D35: 2.01 | E35: Engenheiro - Gerencia de Contrato | H35: Coordenação | I35: Contrato | L35: =meses_obra -> 8 | M35: 16585 | N35: 0 | O35: =IF(I35="CLT","N/A",(L35*(M35/12)*2)) -> 22113.333 | P35: =IF(I35="contrato",AB35,AB35) -> 78.684517 | Q35: =AE35+AF35 -> 0 | R35: =AG35 -> 0 | S35: =Q35*AL35 -> 0 | T35: =R35*AN35 -> 0 | U35: =AW35*L35*J35 -> 0 | Z35: =IF(I35="CLT",(M35/220)*(1+encargos_mensalista),(M35/220)) -> 75.386364 | AA35: =Z35*(1+K35) -> 75.386364 | AB35: =AA35*(1+((incidência_do_dissídio/meses_obra)*dissídio_coletivo)) -> 78.684517 | AC35: =AB35*(1+(ociosidade_por_dia/9)) -> 78.684517 | AE35: =IF(I35="contrato",0,$N$11*$Q$11*$K$11) -> 0 | AF35: =IF(I35="contrato",0,$N$12*$Q$12*$K$12) -> 0 | AG35: =IF(I35="contrato",0,$N$13*$Q$13*$K$13) -> 0 | AH35: =IF(I35="contrato",0,$N$14*$Q$14*$K$14) -> 0 | AI35: =IF(I35="contrato",0,$N$14*$Q$15*$K$15) -> 0 | AJ35: =IF(I35="contrato",0,$N$14*$Q$16*$K$16) -> 0 | AL35: =IF(I35="contrato",0,ROUNDUP((M35/220)*(1+$AA$14)*(1+hora_extra_dias_úteis),2)) -> 0 | AM35: =IF(I35="contrato",0,ROUNDUP((M35/220)*(1+$AA$14)*(1+hora_extra_sábados),2)) -> 0 | AN35: =IF(I35="contrato",0,ROUNDUP((M35/220)*(1+$AA$14)*(1+hora_extra_domingos),2)) -> 0 | AO35: =IF(I35="contrato",0,ROUNDUP(AL35*(1+adicional_noturno),2)) -> 0 | AP35: =IF(I35="contrato",0,ROUNDUP(AM35*(1+adicional_noturno),2)) -> 0 | AQ35: =IF(I35="contrato",0,ROUNDUP(AN35*(1+adicional_noturno),2)) -> 0 | AS35: =IF(H35="Coordenação",0,L35*J35) -> 0 | AT35: =IF(H35="Coordenação",L35*J35,0) -> 0 | AV35: =IF(I35="CLT",IF(L35=0,0,P35*220+N35),(P35*220+N35+(O35/meses_obra))) -> 20074.76 | AW35: =IF(I35="CLT",IF(L35=0,0,((P35*220)+(AE35*AL35)+(AF35*AM35)+(AG35*AN35)+(AH35*AO35)+(AI35*AP35)+(AJ35*AQ35)+N35)),AV35) -> 20074.76 | AX35: =AV35*L35*J35 -> 0
A36: 2 | D36: 2.02 | E36: Engenheiro - Planejamento I | H36: Coordenação | I36: Contrato | L36: =meses_obra -> 8 | M36: 10000 | N36: 0 | O36: =IF(I36="CLT","N/A",(L36*(M36/12)*2)) -> 13333.333 | P36: =IF(I36="contrato",AB36,AB36) -> 47.443182 | Q36: =AE36+AF36 -> 0 | R36: =AG36 -> 0 | S36: =Q36*AL36 -> 0 | T36: =R36*AN36 -> 0 | U36: =AW36*L36*J36 -> 0 | Z36: =IF(I36="CLT",(M36/220)*(1+encargos_mensalista),(M36/220)) -> 45.454545 | AA36: =Z36*(1+K36) -> 45.454545 | AB36: =AA36*(1+((incidência_do_dissídio/meses_obra)*dissídio_coletivo)) -> 47.443182 | AC36: =AB36*(1+(ociosidade_por_dia/9)) -> 47.443182 | AE36: =IF(I36="contrato",0,$N$11*$Q$11*$K$11) -> 0 | AF36: =IF(I36="contrato",0,$N$12*$Q$12*$K$12) -> 0 | AG36: =IF(I36="contrato",0,$N$13*$Q$13*$K$13) -> 0 | AH36: =IF(I36="contrato",0,$N$14*$Q$14*$K$14) -> 0 | AI36: =IF(I36="contrato",0,$N$14*$Q$15*$K$15) -> 0 | AJ36: =IF(I36="contrato",0,$N$14*$Q$16*$K$16) -> 0 | AL36: =IF(I36="contrato",0,ROUNDUP((M36/220)*(1+$AA$14)*(1+hora_extra_dias_úteis),2)) -> 0 | AM36: =IF(I36="contrato",0,ROUNDUP((M36/220)*(1+$AA$14)*(1+hora_extra_sábados),2)) -> 0 | AN36: =IF(I36="contrato",0,ROUNDUP((M36/220)*(1+$AA$14)*(1+hora_extra_domingos),2)) -> 0 | AO36: =IF(I36="contrato",0,ROUNDUP(AL36*(1+adicional_noturno),2)) -> 0 | AP36: =IF(I36="contrato",0,ROUNDUP(AM36*(1+adicional_noturno),2)) -> 0 | AQ36: =IF(I36="contrato",0,ROUNDUP(AN36*(1+adicional_noturno),2)) -> 0 | AS36: =IF(H36="Coordenação",0,L36*J36) -> 0 | AT36: =IF(H36="Coordenação",L36*J36,0) -> 0 | AV36: =IF(I36="CLT",IF(L36=0,0,P36*220+N36),(P36*220+N36+(O36/meses_obra))) -> 12104.167 | AW36: =IF(I36="CLT",IF(L36=0,0,((P36*220)+(AE36*AL36)+(AF36*AM36)+(AG36*AN36)+(AH36*AO36)+(AI36*AP36)+(AJ36*AQ36)+N36)),AV36) -> 12104.167 | AX36: =AV36*L36*J36 -> 0
A37: 2 | D37: 2.03 | E37: Engenheiro - Senior | H37: Coordenação | I37: Contrato | L37: =meses_obra -> 8 | M37: 10000 | N37: 0 | O37: =IF(I37="CLT","N/A",(L37*(M37/12)*2)) -> 13333.333 | P37: =IF(I37="contrato",AB37,AB37) -> 47.443182 | Q37: =AE37+AF37 -> 0 | R37: =AG37 -> 0 | S37: =Q37*AL37 -> 0 | T37: =R37*AN37 -> 0 | U37: =AW37*L37*J37 -> 0 | Z37: =IF(I37="CLT",(M37/220)*(1+encargos_mensalista),(M37/220)) -> 45.454545 | AA37: =Z37*(1+K37) -> 45.454545 | AB37: =AA37*(1+((incidência_do_dissídio/meses_obra)*dissídio_coletivo)) -> 47.443182 | AC37: =AB37*(1+(ociosidade_por_dia/9)) -> 47.443182 | AE37: =IF(I37="contrato",0,$N$11*$Q$11*$K$11) -> 0 | AF37: =IF(I37="contrato",0,$N$12*$Q$12*$K$12) -> 0 | AG37: =IF(I37="contrato",0,$N$13*$Q$13*$K$13) -> 0 | AH37: =IF(I37="contrato",0,$N$14*$Q$14*$K$14) -> 0 | AI37: =IF(I37="contrato",0,$N$14*$Q$15*$K$15) -> 0 | AJ37: =IF(I37="contrato",0,$N$14*$Q$16*$K$16) -> 0 | AL37: =IF(I37="contrato",0,ROUNDUP((M37/220)*(1+$AA$14)*(1+hora_extra_dias_úteis),2)) -> 0 | AM37: =IF(I37="contrato",0,ROUNDUP((M37/220)*(1+$AA$14)*(1+hora_extra_sábados),2)) -> 0 | AN37: =IF(I37="contrato",0,ROUNDUP((M37/220)*(1+$AA$14)*(1+hora_extra_domingos),2)) -> 0 | AO37: =IF(I37="contrato",0,ROUNDUP(AL37*(1+adicional_noturno),2)) -> 0 | AP37: =IF(I37="contrato",0,ROUNDUP(AM37*(1+adicional_noturno),2)) -> 0 | AQ37: =IF(I37="contrato",0,ROUNDUP(AN37*(1+adicional_noturno),2)) -> 0 | AS37: =IF(H37="Coordenação",0,L37*J37) -> 0 | AT37: =IF(H37="Coordenação",L37*J37,0) -> 0 | AV37: =IF(I37="CLT",IF(L37=0,0,P37*220+N37),(P37*220+N37+(O37/meses_obra))) -> 12104.167 | AW37: =IF(I37="CLT",IF(L37=0,0,((P37*220)+(AE37*AL37)+(AF37*AM37)+(AG37*AN37)+(AH37*AO37)+(AI37*AP37)+(AJ37*AQ37)+N37)),AV37) -> 12104.167 | AX37: =AV37*L37*J37 -> 0
A38: 2 | D38: 2.04 | E38: Engenheiro - Produção II | H38: Coordenação | I38: Contrato | J38: 1 | L38: =meses_obra -> 8 | M38: 8000 | N38: 0 | O38: =IF(I38="CLT","N/A",(L38*(M38/12)*2)) -> 10666.667 | P38: =IF(I38="contrato",AB38,AB38) -> 37.954545 | Q38: =AE38+AF38 -> 0 | R38: =AG38 -> 0 | S38: =Q38*AL38 -> 0 | T38: =R38*AN38 -> 0 | U38: =AW38*L38*J38 -> 77466.667 | Z38: =IF(I38="CLT",(M38/220)*(1+encargos_mensalista),(M38/220)) -> 36.363636 | AA38: =Z38*(1+K38) -> 36.363636 | AB38: =AA38*(1+((incidência_do_dissídio/meses_obra)*dissídio_coletivo)) -> 37.954545 | AC38: =AB38*(1+(ociosidade_por_dia/9)) -> 37.954545 | AE38: =IF(I38="contrato",0,$N$11*$Q$11*$K$11) -> 0 | AF38: =IF(I38="contrato",0,$N$12*$Q$12*$K$12) -> 0 | AG38: =IF(I38="contrato",0,$N$13*$Q$13*$K$13) -> 0 | AH38: =IF(I38="contrato",0,$N$14*$Q$14*$K$14) -> 0 | AI38: =IF(I38="contrato",0,$N$14*$Q$15*$K$15) -> 0 | AJ38: =IF(I38="contrato",0,$N$14*$Q$16*$K$16) -> 0 | AL38: =IF(I38="contrato",0,ROUNDUP((M38/220)*(1+$AA$14)*(1+hora_extra_dias_úteis),2)) -> 0 | AM38: =IF(I38="contrato",0,ROUNDUP((M38/220)*(1+$AA$14)*(1+hora_extra_sábados),2)) -> 0 | AN38: =IF(I38="contrato",0,ROUNDUP((M38/220)*(1+$AA$14)*(1+hora_extra_domingos),2)) -> 0 | AO38: =IF(I38="contrato",0,ROUNDUP(AL38*(1+adicional_noturno),2)) -> 0 | AP38: =IF(I38="contrato",0,ROUNDUP(AM38*(1+adicional_noturno),2)) -> 0 | AQ38: =IF(I38="contrato",0,ROUNDUP(AN38*(1+adicional_noturno),2)) -> 0 | AS38: =IF(H38="Coordenação",0,L38*J38) -> 0 | AT38: =IF(H38="Coordenação",L38*J38,0) -> 8 | AV38: =IF(I38="CLT",IF(L38=0,0,P38*220+N38),(P38*220+N38+(O38/meses_obra))) -> 9683.3333 | AW38: =IF(I38="CLT",IF(L38=0,0,((P38*220)+(AE38*AL38)+(AF38*AM38)+(AG38*AN38)+(AH38*AO38)+(AI38*AP38)+(AJ38*AQ38)+N38)),AV38) -> 9683.3333 | AX38: =AV38*L38*J38 -> 77466.667
A39: 2 | D39: 2.05 | E39: Engenheiro - Produção III | H39: Coordenação | I39: Contrato | L39: =meses_obra -> 8 | M39: 6000 | N39: 0 | O39: =IF(I39="CLT","N/A",(L39*(M39/12)*2)) -> 8000 | P39: =IF(I39="contrato",AB39,AB39) -> 28.465909 | Q39: =AE39+AF39 -> 0 | R39: =AG39 -> 0 | S39: =Q39*AL39 -> 0 | T39: =R39*AN39 -> 0 | U39: =AW39*L39*J39 -> 0 | Z39: =IF(I39="CLT",(M39/220)*(1+encargos_mensalista),(M39/220)) -> 27.272727 | AA39: =Z39*(1+K39) -> 27.272727 | AB39: =AA39*(1+((incidência_do_dissídio/meses_obra)*dissídio_coletivo)) -> 28.465909 | AC39: =AB39*(1+(ociosidade_por_dia/9)) -> 28.465909 | AE39: =IF(I39="contrato",0,$N$11*$Q$11*$K$11) -> 0 | AF39: =IF(I39="contrato",0,$N$12*$Q$12*$K$12) -> 0 | AG39: =IF(I39="contrato",0,$N$13*$Q$13*$K$13) -> 0 | AH39: =IF(I39="contrato",0,$N$14*$Q$14*$K$14) -> 0 | AI39: =IF(I39="contrato",0,$N$14*$Q$15*$K$15) -> 0 | AJ39: =IF(I39="contrato",0,$N$14*$Q$16*$K$16) -> 0 | AL39: =IF(I39="contrato",0,ROUNDUP((M39/220)*(1+$AA$14)*(1+hora_extra_dias_úteis),2)) -> 0 | AM39: =IF(I39="contrato",0,ROUNDUP((M39/220)*(1+$AA$14)*(1+hora_extra_sábados),2)) -> 0 | AN39: =IF(I39="contrato",0,ROUNDUP((M39/220)*(1+$AA$14)*(1+hora_extra_domingos),2)) -> 0 | AO39: =IF(I39="contrato",0,ROUNDUP(AL39*(1+adicional_noturno),2)) -> 0 | AP39: =IF(I39="contrato",0,ROUNDUP(AM39*(1+adicional_noturno),2)) -> 0 | AQ39: =IF(I39="contrato",0,ROUNDUP(AN39*(1+adicional_noturno),2)) -> 0 | AS39: =IF(H39="Coordenação",0,L39*J39) -> 0 | AT39: =IF(H39="Coordenação",L39*J39,0) -> 0 | AV39: =IF(I39="CLT",IF(L39=0,0,P39*220+N39),(P39*220+N39+(O39/meses_obra))) -> 7262.5 | AW39: =IF(I39="CLT",IF(L39=0,0,((P39*220)+(AE39*AL39)+(AF39*AM39)+(AG39*AN39)+(AH39*AO39)+(AI39*AP39)+(AJ39*AQ39)+N39)),AV39) -> 7262.5 | AX39: =AV39*L39*J39 -> 0
A40: 2 | D40: 2.06 | E40: Engenheiro - Qualidade | H40: Coordenação | I40: Contrato | L40: =meses_obra -> 8 | M40: 16050 | N40: 0 | O40: =IF(I40="CLT","N/A",(L40*(M40/12)*2)) -> 21400 | P40: =IF(I40="contrato",AB40,AB40) -> 76.146307 | Q40: =AE40+AF40 -> 0 | R40: =AG40 -> 0 | S40: =Q40*AL40 -> 0 | T40: =R40*AN40 -> 0 | U40: =AW40*L40*J40 -> 0 | Z40: =IF(I40="CLT",(M40/220)*(1+encargos_mensalista),(M40/220)) -> 72.954545 | AA40: =Z40*(1+K40) -> 72.954545 | AB40: =AA40*(1+((incidência_do_dissídio/meses_obra)*dissídio_coletivo)) -> 76.146307 | AC40: =AB40*(1+(ociosidade_por_dia/9)) -> 76.146307 | AE40: =IF(I40="contrato",0,$N$11*$Q$11*$K$11) -> 0 | AF40: =IF(I40="contrato",0,$N$12*$Q$12*$K$12) -> 0 | AG40: =IF(I40="contrato",0,$N$13*$Q$13*$K$13) -> 0 | AH40: =IF(I40="contrato",0,$N$14*$Q$14*$K$14) -> 0 | AI40: =IF(I40="contrato",0,$N$14*$Q$15*$K$15) -> 0 | AJ40: =IF(I40="contrato",0,$N$14*$Q$16*$K$16) -> 0 | AL40: =IF(I40="contrato",0,ROUNDUP((M40/220)*(1+$AA$14)*(1+hora_extra_dias_úteis),2)) -> 0 | AM40: =IF(I40="contrato",0,ROUNDUP((M40/220)*(1+$AA$14)*(1+hora_extra_sábados),2)) -> 0 | AN40: =IF(I40="contrato",0,ROUNDUP((M40/220)*(1+$AA$14)*(1+hora_extra_domingos),2)) -> 0 | AO40: =IF(I40="contrato",0,ROUNDUP(AL40*(1+adicional_noturno),2)) -> 0 | AP40: =IF(I40="contrato",0,ROUNDUP(AM40*(1+adicional_noturno),2)) -> 0 | AQ40: =IF(I40="contrato",0,ROUNDUP(AN40*(1+adicional_noturno),2)) -> 0 | AS40: =IF(H40="Coordenação",0,L40*J40) -> 0 | AT40: =IF(H40="Coordenação",L40*J40,0) -> 0 | AV40: =IF(I40="CLT",IF(L40=0,0,P40*220+N40),(P40*220+N40+(O40/meses_obra))) -> 19427.188 | AW40: =IF(I40="CLT",IF(L40=0,0,((P40*220)+(AE40*AL40)+(AF40*AM40)+(AG40*AN40)+(AH40*AO40)+(AI40*AP40)+(AJ40*AQ40)+N40)),AV40) -> 19427.188 | AX40: =AV40*L40*J40 -> 0
A41: 2 | D41: 2.07 | E41: Engenheiro / Arquiteto - Coordenação de Projetos | H41: Coordenação | I41: Contrato | L41: =meses_obra -> 8 | M41: 16050 | N41: 0 | O41: =IF(I41="CLT","N/A",(L41*(M41/12)*2)) -> 21400 | P41: =IF(I41="contrato",AB41,AB41) -> 76.146307 | Q41: =AE41+AF41 -> 0 | R41: =AG41 -> 0 | S41: =Q41*AL41 -> 0 | T41: =R41*AN41 -> 0 | U41: =AW41*L41*J41 -> 0 | Z41: =IF(I41="CLT",(M41/220)*(1+encargos_mensalista),(M41/220)) -> 72.954545 | AA41: =Z41*(1+K41) -> 72.954545 | AB41: =AA41*(1+((incidência_do_dissídio/meses_obra)*dissídio_coletivo)) -> 76.146307 | AC41: =AB41*(1+(ociosidade_por_dia/9)) -> 76.146307 | AE41: =IF(I41="contrato",0,$N$11*$Q$11*$K$11) -> 0 | AF41: =IF(I41="contrato",0,$N$12*$Q$12*$K$12) -> 0 | AG41: =IF(I41="contrato",0,$N$13*$Q$13*$K$13) -> 0 | AH41: =IF(I41="contrato",0,$N$14*$Q$14*$K$14) -> 0 | AI41: =IF(I41="contrato",0,$N$14*$Q$15*$K$15) -> 0 | AJ41: =IF(I41="contrato",0,$N$14*$Q$16*$K$16) -> 0 | AL41: =IF(I41="contrato",0,ROUNDUP((M41/220)*(1+$AA$14)*(1+hora_extra_dias_úteis),2)) -> 0 | AM41: =IF(I41="contrato",0,ROUNDUP((M41/220)*(1+$AA$14)*(1+hora_extra_sábados),2)) -> 0 | AN41: =IF(I41="contrato",0,ROUNDUP((M41/220)*(1+$AA$14)*(1+hora_extra_domingos),2)) -> 0 | AO41: =IF(I41="contrato",0,ROUNDUP(AL41*(1+adicional_noturno),2)) -> 0 | AP41: =IF(I41="contrato",0,ROUNDUP(AM41*(1+adicional_noturno),2)) -> 0 | AQ41: =IF(I41="contrato",0,ROUNDUP(AN41*(1+adicional_noturno),2)) -> 0 | AS41: =IF(H41="Coordenação",0,L41*J41) -> 0 | AT41: =IF(H41="Coordenação",L41*J41,0) -> 0 | AV41: =IF(I41="CLT",IF(L41=0,0,P41*220+N41),(P41*220+N41+(O41/meses_obra))) -> 19427.188 | AW41: =IF(I41="CLT",IF(L41=0,0,((P41*220)+(AE41*AL41)+(AF41*AM41)+(AG41*AN41)+(AH41*AO41)+(AI41*AP41)+(AJ41*AQ41)+N41)),AV41) -> 19427.188 | AX41: =AV41*L41*J41 -> 0
A42: 2 | D42: 2.08 | E42: Tecnológo Civil - Produção | H42: Supervisão | I42: Contrato | L42: =meses_obra -> 8 | M42: 12840 | N42: 0 | O42: =IF(I42="CLT","N/A",(L42*(M42/12)*2)) -> 17120 | P42: =IF(I42="contrato",AB42,AB42) -> 60.917045 | Q42: =AE42+AF42 -> 0 | R42: =AG42 -> 0 | S42: =Q42*AL42 -> 0 | T42: =R42*AN42 -> 0 | U42: =AW42*L42*J42 -> 0 | Z42: =IF(I42="CLT",(M42/220)*(1+encargos_mensalista),(M42/220)) -> 58.363636 | AA42: =Z42*(1+K42) -> 58.363636 | AB42: =AA42*(1+((incidência_do_dissídio/meses_obra)*dissídio_coletivo)) -> 60.917045 | AC42: =AB42*(1+(ociosidade_por_dia/9)) -> 60.917045 | AE42: =IF(I42="contrato",0,$N$11*$Q$11*$K$11) -> 0 | AF42: =IF(I42="contrato",0,$N$12*$Q$12*$K$12) -> 0 | AG42: =IF(I42="contrato",0,$N$13*$Q$13*$K$13) -> 0 | AH42: =IF(I42="contrato",0,$N$14*$Q$14*$K$14) -> 0 | AI42: =IF(I42="contrato",0,$N$14*$Q$15*$K$15) -> 0 | AJ42: =IF(I42="contrato",0,$N$14*$Q$16*$K$16) -> 0 | AL42: =IF(I42="contrato",0,ROUNDUP((M42/220)*(1+$AA$14)*(1+hora_extra_dias_úteis),2)) -> 0 | AM42: =IF(I42="contrato",0,ROUNDUP((M42/220)*(1+$AA$14)*(1+hora_extra_sábados),2)) -> 0 | AN42: =IF(I42="contrato",0,ROUNDUP((M42/220)*(1+$AA$14)*(1+hora_extra_domingos),2)) -> 0 | AO42: =IF(I42="contrato",0,ROUNDUP(AL42*(1+adicional_noturno),2)) -> 0 | AP42: =IF(I42="contrato",0,ROUNDUP(AM42*(1+adicional_noturno),2)) -> 0 | AQ42: =IF(I42="contrato",0,ROUNDUP(AN42*(1+adicional_noturno),2)) -> 0 | AS42: =IF(H42="Coordenação",0,L42*J42) -> 0 | AT42: =IF(H42="Coordenação",L42*J42,0) -> 0 | AV42: =IF(I42="CLT",IF(L42=0,0,P42*220+N42),(P42*220+N42+(O42/meses_obra))) -> 15541.75 | AW42: =IF(I42="CLT",IF(L42=0,0,((P42*220)+(AE42*AL42)+(AF42*AM42)+(AG42*AN42)+(AH42*AO42)+(AI42*AP42)+(AJ42*AQ42)+N42)),AV42) -> 15541.75 | AX42: =AV42*L42*J42 -> 0
A43: 2 | D43: 2.09 | E43: Tecnológo Civil - Planejamento | H43: Supervisão | I43: Contrato | L43: =meses_obra -> 8 | M43: 12840 | N43: 0 | O43: =IF(I43="CLT","N/A",(L43*(M43/12)*2)) -> 17120 | P43: =IF(I43="contrato",AB43,AB43) -> 60.917045 | Q43: =AE43+AF43 -> 0 | R43: =AG43 -> 0 | S43: =Q43*AL43 -> 0 | T43: =R43*AN43 -> 0 | U43: =AW43*L43*J43 -> 0 | Z43: =IF(I43="CLT",(M43/220)*(1+encargos_mensalista),(M43/220)) -> 58.363636 | AA43: =Z43*(1+K43) -> 58.363636 | AB43: =AA43*(1+((incidência_do_dissídio/meses_obra)*dissídio_coletivo)) -> 60.917045 | AC43: =AB43*(1+(ociosidade_por_dia/9)) -> 60.917045 | AE43: =IF(I43="contrato",0,$N$11*$Q$11*$K$11) -> 0 | AF43: =IF(I43="contrato",0,$N$12*$Q$12*$K$12) -> 0 | AG43: =IF(I43="contrato",0,$N$13*$Q$13*$K$13) -> 0 | AH43: =IF(I43="contrato",0,$N$14*$Q$14*$K$14) -> 0 | AI43: =IF(I43="contrato",0,$N$14*$Q$15*$K$15) -> 0 | AJ43: =IF(I43="contrato",0,$N$14*$Q$16*$K$16) -> 0 | AL43: =IF(I43="contrato",0,ROUNDUP((M43/220)*(1+$AA$14)*(1+hora_extra_dias_úteis),2)) -> 0 | AM43: =IF(I43="contrato",0,ROUNDUP((M43/220)*(1+$AA$14)*(1+hora_extra_sábados),2)) -> 0 | AN43: =IF(I43="contrato",0,ROUNDUP((M43/220)*(1+$AA$14)*(1+hora_extra_domingos),2)) -> 0 | AO43: =IF(I43="contrato",0,ROUNDUP(AL43*(1+adicional_noturno),2)) -> 0 | AP43: =IF(I43="contrato",0,ROUNDUP(AM43*(1+adicional_noturno),2)) -> 0 | AQ43: =IF(I43="contrato",0,ROUNDUP(AN43*(1+adicional_noturno),2)) -> 0 | AS43: =IF(H43="Coordenação",0,L43*J43) -> 0 | AT43: =IF(H43="Coordenação",L43*J43,0) -> 0 | AV43: =IF(I43="CLT",IF(L43=0,0,P43*220+N43),(P43*220+N43+(O43/meses_obra))) -> 15541.75 | AW43: =IF(I43="CLT",IF(L43=0,0,((P43*220)+(AE43*AL43)+(AF43*AM43)+(AG43*AN43)+(AH43*AO43)+(AI43*AP43)+(AJ43*AQ43)+N43)),AV43) -> 15541.75 | AX43: =AV43*L43*J43 -> 0
A44: 2 | D44: 2.10 | E44: Tecnológo Civil - Qualidade | H44: Supervisão | I44: Contrato | L44: =meses_obra -> 8 | M44: 12840 | N44: 0 | O44: =IF(I44="CLT","N/A",(L44*(M44/12)*2)) -> 17120 | P44: =IF(I44="contrato",AB44,AB44) -> 60.917045 | Q44: =AE44+AF44 -> 0 | R44: =AG44 -> 0 | S44: =Q44*AL44 -> 0 | T44: =R44*AN44 -> 0 | U44: =AW44*L44*J44 -> 0 | Z44: =IF(I44="CLT",(M44/220)*(1+encargos_mensalista),(M44/220)) -> 58.363636 | AA44: =Z44*(1+K44) -> 58.363636 | AB44: =AA44*(1+((incidência_do_dissídio/meses_obra)*dissídio_coletivo)) -> 60.917045 | AC44: =AB44*(1+(ociosidade_por_dia/9)) -> 60.917045 | AE44: =IF(I44="contrato",0,$N$11*$Q$11*$K$11) -> 0 | AF44: =IF(I44="contrato",0,$N$12*$Q$12*$K$12) -> 0 | AG44: =IF(I44="contrato",0,$N$13*$Q$13*$K$13) -> 0 | AH44: =IF(I44="contrato",0,$N$14*$Q$14*$K$14) -> 0 | AI44: =IF(I44="contrato",0,$N$14*$Q$15*$K$15) -> 0 | AJ44: =IF(I44="contrato",0,$N$14*$Q$16*$K$16) -> 0 | AL44: =IF(I44="contrato",0,ROUNDUP((M44/220)*(1+$AA$14)*(1+hora_extra_dias_úteis),2)) -> 0 | AM44: =IF(I44="contrato",0,ROUNDUP((M44/220)*(1+$AA$14)*(1+hora_extra_sábados),2)) -> 0 | AN44: =IF(I44="contrato",0,ROUNDUP((M44/220)*(1+$AA$14)*(1+hora_extra_domingos),2)) -> 0 | AO44: =IF(I44="contrato",0,ROUNDUP(AL44*(1+adicional_noturno),2)) -> 0 | AP44: =IF(I44="contrato",0,ROUNDUP(AM44*(1+adicional_noturno),2)) -> 0 | AQ44: =IF(I44="contrato",0,ROUNDUP(AN44*(1+adicional_noturno),2)) -> 0 | AS44: =IF(H44="Coordenação",0,L44*J44) -> 0 | AT44: =IF(H44="Coordenação",L44*J44,0) -> 0 | AV44: =IF(I44="CLT",IF(L44=0,0,P44*220+N44),(P44*220+N44+(O44/meses_obra))) -> 15541.75 | AW44: =IF(I44="CLT",IF(L44=0,0,((P44*220)+(AE44*AL44)+(AF44*AM44)+(AG44*AN44)+(AH44*AO44)+(AI44*AP44)+(AJ44*AQ44)+N44)),AV44) -> 15541.75 | AX44: =AV44*L44*J44 -> 0
A45: 2 | D45: 2.11 | E45: Técnico de Edificações - Produção | H45: Supervisão | I45: Contrato | L45: =meses_obra -> 8 | M45: 4000 | N45: 0 | O45: =IF(I45="CLT","N/A",(L45*(M45/12)*2)) -> 5333.3333 | P45: =IF(I45="contrato",AB45,AB45) -> 18.977273 | Q45: =AE45+AF45 -> 0 | R45: =AG45 -> 0 | S45: =Q45*AL45 -> 0 | T45: =R45*AN45 -> 0 | U45: =AW45*L45*J45 -> 0 | Z45: =IF(I45="CLT",(M45/220)*(1+encargos_mensalista),(M45/220)) -> 18.181818 | AA45: =Z45*(1+K45) -> 18.181818 | AB45: =AA45*(1+((incidência_do_dissídio/meses_obra)*dissídio_coletivo)) -> 18.977273 | AC45: =AB45*(1+(ociosidade_por_dia/9)) -> 18.977273 | AE45: =IF(I45="contrato",0,$N$11*$Q$11*$K$11) -> 0 | AF45: =IF(I45="contrato",0,$N$12*$Q$12*$K$12) -> 0 | AG45: =IF(I45="contrato",0,$N$13*$Q$13*$K$13) -> 0 | AH45: =IF(I45="contrato",0,$N$14*$Q$14*$K$14) -> 0 | AI45: =IF(I45="contrato",0,$N$14*$Q$15*$K$15) -> 0 | AJ45: =IF(I45="contrato",0,$N$14*$Q$16*$K$16) -> 0 | AL45: =IF(I45="contrato",0,ROUNDUP((M45/220)*(1+$AA$14)*(1+hora_extra_dias_úteis),2)) -> 0 | AM45: =IF(I45="contrato",0,ROUNDUP((M45/220)*(1+$AA$14)*(1+hora_extra_sábados),2)) -> 0 | AN45: =IF(I45="contrato",0,ROUNDUP((M45/220)*(1+$AA$14)*(1+hora_extra_domingos),2)) -> 0 | AO45: =IF(I45="contrato",0,ROUNDUP(AL45*(1+adicional_noturno),2)) -> 0 | AP45: =IF(I45="contrato",0,ROUNDUP(AM45*(1+adicional_noturno),2)) -> 0 | AQ45: =IF(I45="contrato",0,ROUNDUP(AN45*(1+adicional_noturno),2)) -> 0 | AS45: =IF(H45="Coordenação",0,L45*J45) -> 0 | AT45: =IF(H45="Coordenação",L45*J45,0) -> 0 | AV45: =IF(I45="CLT",IF(L45=0,0,P45*220+N45),(P45*220+N45+(O45/meses_obra))) -> 4841.6667 | AW45: =IF(I45="CLT",IF(L45=0,0,((P45*220)+(AE45*AL45)+(AF45*AM45)+(AG45*AN45)+(AH45*AO45)+(AI45*AP45)+(AJ45*AQ45)+N45)),AV45) -> 4841.6667 | AX45: =AV45*L45*J45 -> 0
...

Sheet F.D.
B2: FATURAMENTO DIRETO | K2: RESUMO - FD
B4: Cód. Insumo | C4: Descrição | D4: Unidade | E4: Qtd Orçada | F4: Unt Insumo | G4: ∑ Insumo | H4: Fornecedor | K4: FORNECEDOR | L4: TOTAL
L6: =SUMIF($H$119:$H$170,K6,$G$119:$G$170) -> 0
B7: 34.45.27 | C7: Piso em porcelanato Firenze Brilhante 64x64 cm - Porto Ferreira | D7: m² | E7: 5303.021 | F7: 60 | G7: 318181.26 | L7: =SUMIF($H$119:$H$170,K7,$G$119:$G$170) -> 0
B8: 34.46.01 | C8: Revestimento Glacial Snow 32x59 cm branco acetinado RET - Incepa | D8: m² | E8: 5215.056 | F8: 60 | G8: 312903.36 | L8: =SUMIF($H$119:$H$170,K8,$G$119:$G$170) -> 0
L9: =SUMIF($H$119:$H$170,K9,$G$119:$G$170) -> 0
L10: =SUMIF($H$119:$H$170,K10,$G$119:$G$170) -> 0
B11: 37.70.89 | C11: Vidro temperado incolor 8 mm | D11: m² | E11: 805.752 | F11: 266.475 | G11: 214712.76
B12: 20.05.80 | C12: Gesso em pó ensacado para revestimento saco de 40 kg | D12: kg | E12: 184062.91 | F12: 0.95975 | G12: 176654.38 | L12: =SUMIF($H$119:$H$170,K12,$G$119:$G$170) -> 0
L13: =SUMIF($H$119:$H$170,K13,$G$119:$G$170) -> 0
B14: 90.06.32 | C14: Caixilho em alumínio anodizado fosco L 25, tipo veneziana, sob medida | D14: m² | E14: 328.428 | F14: 504.68154 | G14: 165751.55 | L14: =SUMIF($H$119:$H$170,K14,$G$119:$G$170) -> 0
L15: =SUMIF($H$119:$H$170,K15,$G$119:$G$170) -> 0
B16: 65.55.02 | C16: Bacia para Caixa Acoplada Deca | Ravena - Branco | D16: un | E16: 220 | F16: 620.9 | G16: 136598 | L16: =SUMIF($H$119:$H$170,K16,$G$119:$G$170) -> 0
L17: =SUMIF($H$119:$H$170,K17,$G$119:$G$170) -> 0
B18: 20.05.03 | C18: Areia média lavada à granel | D18: m³ | E18: 951.84032 | F18: 96 | G18: 91376.671 | L18: =SUMIF($H$119:$H$170,K18,$G$119:$G$170) -> 0
B19: 34.45.97 | C19: Clipe espaçador nivelador em plástico 1 mm para pisos | D19: un | E19: 194822 | F19: 0.46 | G19: 89618.12 | L19: =SUMIF($H$119:$H$170,K19,$G$119:$G$170) -> 0
B20: 20.05.08 | C20: Cimento CPIII-E-32 (sacos de 50 kg) (volume do saco 0,036 m³) | D20: kg | E20: 145495.36 | F20: 0.61 | G20: 88752.17 | L20: =SUMIF($H$119:$H$170,K20,$G$119:$G$170) -> 0
B21: 37.75.20 | C21: Tinta direto sobre gesso e drywall 18 L - diluição de 50% Clássica máxx branco neve Suvinil | D21: l | E21: 4364.6075 | F21: 18.327778 | G21: 79993.556 | L21: =SUMIF($H$119:$H$170,K21,$G$119:$G$170) -> 0
B22: 99.50.21 | C22: Cuba Apoio Quadrada Basic Q6 35x35cm Com Mesa Branco Celite | D22: un | E22: 220 | F22: 359.91 | G22: 79180.2 | L22: =SUMIF($H$119:$H$170,K22,$G$119:$G$170) -> 0
L23: =SUMIF($H$119:$H$170,K23,$G$119:$G$170) -> 0
L24: =SUMIF($H$119:$H$170,K24,$G$119:$G$170) -> 0
B25: 30.02.23 | C25: Folha de porta lisa em madeira sarrafeada para pintura 82x210cm | D25: un | E25: 245 | F25: 270 | G25: 66150 | L25: =SUMIF($H$119:$H$170,K25,$G$119:$G$170) -> 0
B26: 30.01.35 | C26: Batente madeira itauba/garapeira/cedro/angelim 13x3,5cm, vão 52 a 92x210cm | D26: un | E26: 264 | F26: 250 | G26: 66000 | L26: =SUMIF($H$119:$H$170,K26,$G$119:$G$170) -> 0
B27: 39.90.56 | C27: Argamassa química bicomponente para porcelanato, alta resistência química, térmicas e vibrações, AC-III | D27: kg | E27: 26075.28 | F27: 2.45 | G27: 63884.436 | L27: =SUMIF($H$119:$H$170,K27,$G$119:$G$170) -> 0
B28: 98.81.76 | C28: Limpeza e final da obra terceirizado especializado | D28: m² | E28: 5435.72 | F28: 11 | G28: 59792.92 | L28: =SUMIF($H$119:$H$170,K28,$G$119:$G$170) -> 0
B29: 37.75.10 | C29: Massa corrida de base Acrílica - Suvinil/Glasurit, Massa FC (Fusecolor), Massa Especial para fachada (Retinco) ou equivalente | D29: kg | E29: 8834.9333 | F29: 6.76 | G29: 59724.149 | L29: =SUMIF($H$119:$H$170,K29,$G$119:$G$170) -> 0
B30: 34.40.48 | C30: Chapa de gesso acartonado, ref. Gypsum Standard 12.5 mm 1200x1800 mm | D30: m² | E30: 2229.669 | F30: 26.347222 | G30: 58745.585 | L30: =SUMIF($H$119:$H$170,K30,$G$119:$G$170) -> 0
B31: 35.50.72 | C31: Mármore Travertino Nacional; espessura de 2,0 cm colocado | D31: m² | E31: 119.9744 | F31: 482.22 | G31: 57854.055 | L31: =SUMIF($H$119:$H$170,K31,$G$119:$G$170) -> 0
B32: 30.01.37 | C32: Batente madeira itauba/garapeira/cedro/angelim 11x3,5cm, vão 122x210cm | D32: un | E32: 228 | F32: 240 | G32: 54720 | L32: =SUMIF($H$119:$H$170,K32,$G$119:$G$170) -> 0
B33: 30.02.22 | C33: Folha de porta lisa em madeira sarrafeada para pintura 72x210cm | D33: un | E33: 228 | F33: 240 | G33: 54720 | L33: =SUMIF($H$119:$H$170,K33,$G$119:$G$170) -> 0
B34: 37.70.26 | C34: Espelho em vidro cristal liso, espessura de 4 mm, colocado sobre a parede, peças aproximadamente 0,5 a 4,12 m² | D34: m² | E34: 138.2 | F34: 387.52 | G34: 53555.264 | L34: =SUMIF($H$119:$H$170,K34,$G$119:$G$170) -> 0
B35: 39.90.24 | C35: Viaplus 1000 | D35: kg | E35: 14946.64 | F35: 3.4772222 | G35: 51972.789 | L35: =SUMIF($H$119:$H$170,K35,$G$119:$G$170) -> 0
B36: 99.50.93 | C36: Porta toalhas bastão toalheiro docol Trip Cromado | D36: un | E36: 222 | F36: 202.45 | G36: 44943.9 | L36: =SUMIF($H$119:$H$170,K36,$G$119:$G$170) -> 0
... B38: 64.45.03 | C38: Sifão metálico cromado 1´ x 1 1/2´, com tubo de ligação ajustável; ref. Fabrimar, Oriente ou equivalente | D38: un | E38: 235 | F38: 187 | G38: 43945 | L38: =SUMIF($H$119:$H$170,K38,$G$119:$G$170) -> 0
L39: =SUMIF($H$119:$H$170,K39,$G$119:$G$170) -> 0
B40: 31.16.45 | C40: Dobradiça em latão cromado de 3 1/2´ x 3´, ref. La Fonte Dob 90 3 1/2´ x 3´ LT S/P CR, Arouca 346, 3500 da União Mundial ou equivalente | D40: un | E40: 984 | F40: 39.9 | G40: 39261.6 | L40: =SUMIF($H$119:$H$170,K40,$G$119:$G$170) -> 0
B41: 22.25.40 | C41: Bloco cerâmico para vedação 9 x 19 x 29 cm, uso revestido, ± 3,0 MPa | D41: un | E41: 25538.012 | F41: 1.49 | G41: 38051.637 | L41: =SUMIF($H$119:$H$170,K41,$G$119:$G$170) -> 0
B42: 99.50.95 | C42: Papeleira Trip, Docol, Cromado | D42: un | E42: 222 | F42: 170.91 | G42: 37942.02 | L42: =SUMIF($H$119:$H$170,K42,$G$119:$G$170) -> 0
B43: 32.25.14 | C43: Granto Preto São Gabriel, acabamento polido, espessura de 2 cm | D43: m² | E43: 71.688 | F43: 480 | G43: 34410.24 | L43: =SUMIF($H$119:$H$170,K43,$G$119:$G$170) -> 0
L44: =SUMIF($H$119:$H$170,K44,$G$119:$G$170) -> 0
...

Sheet Bdi CURVA ABC - MAT
B2: BDI CURVA ABC DE MATERIAIS | K2: RESUMO - FD
B4: Cód. Insumo | C4: Descrição | D4: Unidade | E4: Qtd Orçada | F4: Unt Insumo | G4: ∑ Insumo | H4: Fornecedor | K4: FORNECEDOR | L4: TOTAL
K5: {=IFERROR(_xlfn.UNIQUE(H5:H209),"")} -> 0 | L5: =SUMIF($H$5:$H$259,K5,$G$5:$G$259) -> 0
L6: =SUMIF($H$5:$H$259,K6,$G$5:$G$259) -> 0
L7: =SUMIF($H$5:$H$259,K7,$G$5:$G$259) -> 0
L8: =SUMIF($H$5:$H$259,K8,$G$5:$G$259) -> 0
L9: =SUMIF($H$5:$H$259,K9,$G$5:$G$259) -> 0
L10: =SUMIF($H$5:$H$259,K10,$G$5:$G$259) -> 0
L11: =SUMIF($H$5:$H$259,K11,$G$5:$G$259) -> 0
L12: =SUMIF($H$5:$H$259,K12,$G$5:$G$259) -> 0
L13: =SUMIF($H$5:$H$259,K13,$G$5:$G$259) -> 0
L14: =SUMIF($H$5:$H$259,K14,$G$5:$G$259) -> 0
L15: =SUMIF($H$5:$H$259,K15,$G$5:$G$259) -> 0
L16: =SUMIF($H$5:$H$259,K16,$G$5:$G$259) -> 0
L17: =SUMIF($H$5:$H$259,K17,$G$5:$G$259) -> 0
... L209: =SUMIF($H$5:$H$259,K209,$G$5:$G$259) -> 0
B210: TOTAL | H210: =SUM(G5:G205) -> 0 | L210: =SUMIF($H$5:$H$259,K210,$G$5:$G$259) -> 0
L211: =SUMIF($H$5:$H$259,K211,$G$5:$G$259) -> 0
L212: =SUMIF($H$5:$H$259,K212,$G$5:$G$259) -> 0
L213: =SUMIF($H$5:$H$259,K213,$G$5:$G$259) -> 0
L214: =SUMIF($H$5:$H$259,K214,$G$5:$G$259) -> 0
L215: =SUMIF($H$5:$H$259,K215,$G$5:$G$259) -> 0
L216: =SUMIF($H$5:$H$259,K216,$G$5:$G$259) -> 0
L217: =SUMIF($H$5:$H$259,K217,$G$5:$G$259) -> 0
L218: =SUMIF($H$5:$H$259,K218,$G$5:$G$259) -> 0
L219: =SUMIF($H$5:$H$259,K219,$G$5:$G$259) -> 0
K220: TOTAL | L220: =SUM(L5:L217) -> 0

Sheet Adm Central
G2: ADM Central | K2: Materiais = | L2: =materiais -> 3265572.7
G3: =BDI!F3 -> FC ENGENHARIA E CONSULTORIA LTDA | K3: Mão de Obra = | L3: =mdo+hora_extra_mdo_direta+transf_diss_ocio_mdo_direta -> 2433374.6
G4: =BDI!F4 -> julho/19 - Com desoneração da Folha de Pagamento | K4: Σ = | L4: =SUM(L2:L3) -> 5698947.3
D6: Obra: | E6: =" "&nome_da_obra -> BDI_747.xlsx | K6: Data base: | L6: =data_base_da_obra -> 46093
A8: =D8 -> 1 | B8: =D8 -> 1 | D8: 1 | F8: Pessoal: | H8: Base | I8: Tempo (Obra) | J8: Encargos | K8: Benefícios | L8: Total
A9: =IF(OFFSET(A9,-1,0)="",OFFSET(A9,-2,0),OFFSET(A9,-1,0)) -> 1 | B9: =IF(OFFSET(B9,-1,0)>="01",CONCATENATE(,OFFSET(B9,-1,0)+1),CONCATENATE((SUM(OFFSET(B9,-1,0)+1-(OFFSET(B9,-1,0)))))) -> 1 | E9: =IF(B9="1",CONCATENATE(A9,".0",B9),IF(B9="2",CONCATENATE(A9,".0",B9),IF(B9="3",CONCATENATE(A9,".0",B9),IF(B9="4",CONCATENATE(A9,".0",B9),IF(B9="5",CONCATENATE(A9,".0",B9),IF(B9="6",CONCATENATE(A9,".0",B9),IF(B9="7",CONCATENATE(A9,".0",B9),IF(B9="8",CONCATENATE(A9,".0",B9),IF(B9="9",CONCATENATE(A9,".0",B9),CONCATENATE(A9,".",B9)))))))))) -> 1.01 | F9: Diretoria 1 | I9: =meses_obra -> 8 | J9: 0 | K9: 0 | L9: =((H9*J9)+H9+K9)*I9 -> 0
A10: =IF(OFFSET(A10,-1,0)="",OFFSET(A10,-2,0),OFFSET(A10,-1,0)) -> 1 | B10: =IF(OFFSET(B10,-1,0)>="01",CONCATENATE(,OFFSET(B10,-1,0)+1),CONCATENATE((SUM(OFFSET(B10,-1,0)+1-(OFFSET(B10,-1,0)))))) -> 2 | E10: =IF(B10="1",CONCATENATE(A10,".0",B10),IF(B10="2",CONCATENATE(A10,".0",B10),IF(B10="3",CONCATENATE(A10,".0",B10),IF(B10="4",CONCATENATE(A10,".0",B10),IF(B10="5",CONCATENATE(A10,".0",B10),IF(B10="6",CONCATENATE(A10,".0",B10),IF(B10="7",CONCATENATE(A10,".0",B10),IF(B10="8",CONCATENATE(A10,".0",B10),IF(B10="9",CONCATENATE(A10,".0",B10),CONCATENATE(A10,".",B10)))))))))) -> 1.02 | F10: Diretoria 2 | I10: =I$9 -> 8 | J10: 0 | K10: 0 | L10: =((H10*J10)+H10+K10)*I10 -> 0
A11: =IF(OFFSET(A11,-1,0)="",OFFSET(A11,-2,0),OFFSET(A11,-1,0)) -> 1 | B11: =IF(OFFSET(B11,-1,0)>="01",CONCATENATE(,OFFSET(B11,-1,0)+1),CONCATENATE((SUM(OFFSET(B11,-1,0)+1-(OFFSET(B11,-1,0)))))) -> 3 | E11: =IF(B11="1",CONCATENATE(A11,".0",B11),IF(B11="2",CONCATENATE(A11,".0",B11),IF(B11="3",CONCATENATE(A11,".0",B11),IF(B11="4",CONCATENATE(A11,".0",B11),IF(B11="5",CONCATENATE(A11,".0",B11),IF(B11="6",CONCATENATE(A11,".0",B11),IF(B11="7",CONCATENATE(A11,".0",B11),IF(B11="8",CONCATENATE(A11,".0",B11),IF(B11="9",CONCATENATE(A11,".0",B11),CONCATENATE(A11,".",B11)))))))))) -> 1.03 | F11: Diretoria 3 | I11: =I$9 -> 8 | J11: 0.973 | K11: 0 | L11: =((H11*J11)+H11+K11)*I11 -> 0
A12: =IF(OFFSET(A12,-1,0)="",OFFSET(A12,-2,0),OFFSET(A12,-1,0)) -> 1 | B12: =IF(OFFSET(B12,-1,0)>="01",CONCATENATE(,OFFSET(B12,-1,0)+1),CONCATENATE((SUM(OFFSET(B12,-1,0)+1-(OFFSET(B12,-1,0)))))) -> 4 | E12: =IF(B12="1",CONCATENATE(A12,".0",B12),IF(B12="2",CONCATENATE(A12,".0",B12),IF(B12="3",CONCATENATE(A12,".0",B12),IF(B12="4",CONCATENATE(A12,".0",B12),IF(B12="5",CONCATENATE(A12,".0",B12),IF(B12="6",CONCATENATE(A12,".0",B12),IF(B12="7",CONCATENATE(A12,".0",B12),IF(B12="8",CONCATENATE(A12,".0",B12),IF(B12="9",CONCATENATE(A12,".0",B12),CONCATENATE(A12,".",B12)))))))))) -> 1.04 | F12: Diretoria 4 | I12: =I$9 -> 8 | J12: 0 | K12: 0 | L12: =((H12*J12)+H12+K12)*I12 -> 0
A13: =IF(OFFSET(A13,-1,0)="",OFFSET(A13,-2,0),OFFSET(A13,-1,0)) -> 1 | B13: =IF(OFFSET(B13,-1,0)>="01",CONCATENATE(,OFFSET(B13,-1,0)+1),CONCATENATE((SUM(OFFSET(B13,-1,0)+1-(OFFSET(B13,-1,0)))))) -> 5 | E13: =IF(B13="1",CONCATENATE(A13,".0",B13),IF(B13="2",CONCATENATE(A13,".0",B13),IF(B13="3",CONCATENATE(A13,".0",B13),IF(B13="4",CONCATENATE(A13,".0",B13),IF(B13="5",CONCATENATE(A13,".0",B13),IF(B13="6",CONCATENATE(A13,".0",B13),IF(B13="7",CONCATENATE(A13,".0",B13),IF(B13="8",CONCATENATE(A13,".0",B13),IF(B13="9",CONCATENATE(A13,".0",B13),CONCATENATE(A13,".",B13)))))))))) -> 1.05 | F13: Orçamentos 1 | I13: =I$9 -> 8 | J13: 0 | K13: 0 | L13: =((H13*J13)+H13+K13)*I13 -> 0
A14: =IF(OFFSET(A14,-1,0)="",OFFSET(A14,-2,0),OFFSET(A14,-1,0)) -> 1 | B14: =IF(OFFSET(B14,-1,0)>="01",CONCATENATE(,OFFSET(B14,-1,0)+1),CONCATENATE((SUM(OFFSET(B14,-1,0)+1-(OFFSET(B14,-1,0)))))) -> 6 | E14: =IF(B14="1",CONCATENATE(A14,".0",B14),IF(B14="2",CONCATENATE(A14,".0",B14),IF(B14="3",CONCATENATE(A14,".0",B14),IF(B14="4",CONCATENATE(A14,".0",B14),IF(B14="5",CONCATENATE(A14,".0",B14),IF(B14="6",CONCATENATE(A14,".0",B14),IF(B14="7",CONCATENATE(A14,".0",B14),IF(B14="8",CONCATENATE(A14,".0",B14),IF(B14="9",CONCATENATE(A14,".0",B14),CONCATENATE(A14,".",B14)))))))))) -> 1.06 | F14: Orçamentos 2 | I14: =I$9 -> 8 | J14: 0.973 | K14: 0 | L14: =((H14*J14)+H14+K14)*I14 -> 0
A15: =IF(OFFSET(A15,-1,0)="",OFFSET(A15,-2,0),OFFSET(A15,-1,0)) -> 1 | B15: =IF(OFFSET(B15,-1,0)>="01",CONCATENATE(,OFFSET(B15,-1,0)+1),CONCATENATE((SUM(OFFSET(B15,-1,0)+1-(OFFSET(B15,-1,0)))))) -> 7 | E15: =IF(B15="1",CONCATENATE(A15,".0",B15),IF(B15="2",CONCATENATE(A15,".0",B15),IF(B15="3",CONCATENATE(A15,".0",B15),IF(B15="4",CONCATENATE(A15,".0",B15),IF(B15="5",CONCATENATE(A15,".0",B15),IF(B15="6",CONCATENATE(A15,".0",B15),IF(B15="7",CONCATENATE(A15,".0",B15),IF(B15="8",CONCATENATE(A15,".0",B15),IF(B15="9",CONCATENATE(A15,".0",B15),CONCATENATE(A15,".",B15)))))))))) -> 1.07 | F15: Orçamentos 3 | I15: =I$9 -> 8 | J15: 0 | K15: 0 | L15: =((H15*J15)+H15+K15)*I15 -> 0
A16: =IF(OFFSET(A16,-1,0)="",OFFSET(A16,-2,0),OFFSET(A16,-1,0)) -> 1 | B16: =IF(OFFSET(B16,-1,0)>="01",CONCATENATE(,OFFSET(B16,-1,0)+1),CONCATENATE((SUM(OFFSET(B16,-1,0)+1-(OFFSET(B16,-1,0)))))) -> 8 | E16: =IF(B16="1",CONCATENATE(A16,".0",B16),IF(B16="2",CONCATENATE(A16,".0",B16),IF(B16="3",CONCATENATE(A16,".0",B16),IF(B16="4",CONCATENATE(A16,".0",B16),IF(B16="5",CONCATENATE(A16,".0",B16),IF(B16="6",CONCATENATE(A16,".0",B16),IF(B16="7",CONCATENATE(A16,".0",B16),IF(B16="8",CONCATENATE(A16,".0",B16),IF(B16="9",CONCATENATE(A16,".0",B16),CONCATENATE(A16,".",B16)))))))))) -> 1.08 | F16: Planejamento 1 | I16: =I$9 -> 8 | J16: 0 | K16: 0 | L16: =((H16*J16)+H16+K16)*I16 -> 0
A17: =IF(OFFSET(A17,-1,0)="",OFFSET(A17,-2,0),OFFSET(A17,-1,0)) -> 1 | B17: =IF(OFFSET(B17,-1,0)>="01",CONCATENATE(,OFFSET(B17,-1,0)+1),CONCATENATE((SUM(OFFSET(B17,-1,0)+1-(OFFSET(B17,-1,0)))))) -> 9 | E17: =IF(B17="1",CONCATENATE(A17,".0",B17),IF(B17="2",CONCATENATE(A17,".0",B17),IF(B17="3",CONCATENATE(A17,".0",B17),IF(B17="4",CONCATENATE(A17,".0",B17),IF(B17="5",CONCATENATE(A17,".0",B17),IF(B17="6",CONCATENATE(A17,".0",B17),IF(B17="7",CONCATENATE(A17,".0",B17),IF(B17="8",CONCATENATE(A17,".0",B17),IF(B17="9",CONCATENATE(A17,".0",B17),CONCATENATE(A17,".",B17)))))))))) -> 1.09 | F17: Planejamento 2 | I17: =I$9 -> 8 | J17: 0 | K17: 0 | L17: =((H17*J17)+H17+K17)*I17 -> 0
A18: =IF(OFFSET(A18,-1,0)="",OFFSET(A18,-2,0),OFFSET(A18,-1,0)) -> 1 | B18: =IF(OFFSET(B18,-1,0)>="01",CONCATENATE(,OFFSET(B18,-1,0)+1),CONCATENATE((SUM(OFFSET(B18,-1,0)+1-(OFFSET(B18,-1,0)))))) -> 10 | E18: =IF(B18="1",CONCATENATE(A18,".0",B18),IF(B18="2",CONCATENATE(A18,".0",B18),IF(B18="3",CONCATENATE(A18,".0",B18),IF(B18="4",CONCATENATE(A18,".0",B18),IF(B18="5",CONCATENATE(A18,".0",B18),IF(B18="6",CONCATENATE(A18,".0",B18),IF(B18="7",CONCATENATE(A18,".0",B18),IF(B18="8",CONCATENATE(A18,".0",B18),IF(B18="9",CONCATENATE(A18,".0",B18),CONCATENATE(A18,".",B18)))))))))) -> 1.10 | F18: Setor Tecnologia | I18: =I$9 -> 8 | J18: 0 | K18: 0 | L18: =((H18*J18)+H18+K18)*I18 -> 0
A19: =IF(OFFSET(A19,-1,0)="",OFFSET(A19,-2,0),OFFSET(A19,-1,0)) -> 1 | B19: =IF(OFFSET(B19,-1,0)>="01",CONCATENATE(,OFFSET(B19,-1,0)+1),CONCATENATE((SUM(OFFSET(B19,-1,0)+1-(OFFSET(B19,-1,0)))))) -> 11 | E19: =IF(B19="1",CONCATENATE(A19,".0",B19),IF(B19="2",CONCATENATE(A19,".0",B19),IF(B19="3",CONCATENATE(A19,".0",B19),IF(B19="4",CONCATENATE(A19,".0",B19),IF(B19="5",CONCATENATE(A19,".0",B19),IF(B19="6",CONCATENATE(A19,".0",B19),IF(B19="7",CONCATENATE(A19,".0",B19),IF(B19="8",CONCATENATE(A19,".0",B19),IF(B19="9",CONCATENATE(A19,".0",B19),CONCATENATE(A19,".",B19)))))))))) -> 1.11 | F19: Recursos Humanos 1 | I19: =I$9 -> 8 | J19: 0.973 | K19: 0 | L19: =((H19*J19)+H19+K19)*I19 -> 0
