Workbook

Sheet REFIS
I2: RELATÓRIO DE EVOLUÇÃO FÍSICA DA OBRA (REFIS)
I3: R00 | N3: OBRA: | O3: HOTEL QIU II - FASE 4
I4: BASE: PLN_747_09_2025_R02_HOTEL QIU 2 - FASE 4 | N4: LOCAL: | O4: APARECIDA/SP
I5: RELAT N°01 | N5: CLIENTE: | O5: QIU XIANQUAN
C8: INÍCIO: | D8: 46048 | H8: STATUS EM: | I8: 46073 | N8: TÉRMINO DA OBRA: | O8: 46366
I90: RELATÓRIO DE EVOLUÇÃO FÍSICA DA OBRA (REFIS)
I91: R00 | N91: OBRA: | O91: HOTEL QIU II - FASE 4
I92: BASE: PLN_747_09_2025_R02_HOTEL QIU 2 - FASE 4 | N92: LOCAL: | O92: APARECIDA/SP
I93: RELAT N°01 | N93: CLIENTE: | O93: QIU XIANQUAN
C96: INÍCIO: | D96: 46048 | H96: STATUS EM: | I96: 46073 | N96: TÉRMINO DA OBRA: | O96: 46366
B98: ATIVIDADES PREVISTAS POR SEMANA
B99: SEMANA 12 - 18 a 24/10 | G99: SEMANA 13 - 25 a 31/10 | M99: SEMANA 14 - 01 a 07/11

Sheet DADOS
D2: 1º | F2: 2º | H2: 3º | J2: 4º | L2: 5º | N2: 6º | P2: 7º | R2: 8º | T2: 9º | V2: 10º | X2: 11º | Z2: 12º | AB2: 13º | AD2: 14º | AF2: 15º | AH2: 16º | AJ2: 17º | AL2: 18º | AN2: 19º | AP2: 20º | AR2: 21º | AT2: 22º | AV2: 23º | AX2: 24º | AZ2: 25º | BB2: 26º | BD2: 27º | BF2: 28º | BH2: 29º | BJ2: 30º | BL2: 31º | BN2: 32º | BP2: 33º | BR2: 34º | BT2: 35º | BV2: 36º | BX2: 37º | BZ2: 38º | CB2: 39º | CD2: 40º | CF2: 41º | CH2: 42º | CJ2: 43º | CL2: 44º | CN2: 45º | CP2: 46º | CR2: 47º | CT2: 48º | CV2: 49º | CX2: 50º | CZ2: 51º | DB2: 52º | DD2: 53º | DF2: 54º | DH2: 55º | DJ2: 56º | DL2: 57º | DN2: 58º | DP2: 59º | DR2: 60º | DT2: 61º | DV2: 81º | DX2: 82º | DZ2: 83º | EB2: 84º | ED2: 85º | EF2: 86º | EH2: 87º | EJ2: 88º | EL2: 89º | EN2: 90º | EP2: 91º | ER2: 92º | ET2: 93º | EV2: 94º
A3: SEMANA: | B3: 4º | C3: Status: | D3: 46051 | F3: =D3+7 -> 46058 | H3: =F3+7 -> 46065 | J3: =H3+7 -> 46072 | L3: =J3+7 -> 46079 | N3: =L3+7 -> 46086 | P3: =N3+7 -> 46093 | R3: =P3+7 -> 46100 | T3: =R3+7 -> 46107 | V3: =T3+7 -> 46114 | X3: =V3+7 -> 46121 | Z3: =X3+7 -> 46128 | AB3: =Z3+7 -> 46135 | AD3: =AB3+7 -> 46142 | AF3: =AD3+7 -> 46149 | AH3: =AF3+7 -> 46156 | AJ3: =AH3+7 -> 46163 | AL3: =AJ3+7 -> 46170 | AN3: =AL3+7 -> 46177 | AP3: =AN3+7 -> 46184 | AR3: =AP3+7 -> 46191 | AT3: =AR3+7 -> 46198 | AV3: =AT3+7 -> 46205 | AX3: =AV3+7 -> 46212 | AZ3: =AX3+7 -> 46219 | BB3: =AZ3+7 -> 46226 | BD3: =BB3+7 -> 46233 | BF3: =BD3+7 -> 46240 | BH3: =BF3+7 -> 46247 | BJ3: =BH3+7 -> 46254 | BL3: =BJ3+7 -> 46261 | BN3: =BL3+7 -> 46268 | BP3: =BN3+7 -> 46275 | BR3: =BP3+7 -> 46282 | BT3: =BR3+7 -> 46289 | BV3: =BT3+7 -> 46296 | BX3: =BV3+7 -> 46303 | BZ3: =BX3+7 -> 46310 | CB3: =BZ3+7 -> 46317 | CD3: =CB3+7 -> 46324 | CF3: =CD3+7 -> 46331 | CH3: =CF3+7 -> 46338 | CJ3: =CH3+7 -> 46345 | CL3: =CJ3+7 -> 46352 | CN3: =CL3+7 -> 46359 | CP3: =CN3+7 -> 46366 | CR3: =CP3+7 -> 46373 | CT3: =CR3+7 -> 46380 | CV3: =CT3+7 -> 46387 | CX3: =CV3+7 -> 46394 | CZ3: =CX3+7 -> 46401 | DB3: =CZ3+7 -> 46408 | DD3: =DB3+7 -> 46415 | DF3: =DD3+7 -> 46422 | DH3: =DF3+7 -> 46429 | DJ3: =DH3+7 -> 46436 | DL3: =DJ3+7 -> 46443 | DN3: =DL3+7 -> 46450 | DP3: =DN3+7 -> 46457 | DR3: =DP3+7 -> 46464 | DT3: =DR3+7 -> 46471 | DV3: =DT3+7 -> 46478 | DX3: =DV3+7 -> 46485 | DZ3: =DX3+7 -> 46492 | EB3: =DZ3+7 -> 46499 | ED3: =EB3+7 -> 46506 | EF3: =ED3+7 -> 46513 | EH3: =EF3+7 -> 46520 | EJ3: =EH3+7 -> 46527 | EL3: =EJ3+7 -> 46534 | EN3: =EL3+7 -> 46541 | EP3: =EN3+7 -> 46548 | ER3: =EP3+7 -> 46555 | ET3: =ER3+7 -> 46562 | EV3: =ET3+7 -> 46569
A4: % REALIZADO | B4: % PREVISTO | C4: Descrição | D4: % concluída | E4: % PREVISTO | F4: % concluída | G4: % PREVISTO | H4: % concluída | I4: % PREVISTO | J4: % concluída | K4: % PREVISTO | L4: % concluída | M4: % PREVISTO | N4: % concluída | O4: % PREVISTO | P4: % concluída | Q4: % PREVISTO | R4: % concluída | S4: % PREVISTO | T4: % concluída | U4: % PREVISTO | V4: % concluída | W4: % PREVISTO | X4: % concluída | Y4: % PREVISTO | Z4: % concluída | AA4: % PREVISTO | AB4: % concluída | AC4: % PREVISTO | AD4: % concluída | AE4: % PREVISTO | AF4: % concluída | AG4: % PREVISTO | AH4: % concluída | AI4: % PREVISTO | AJ4: % concluída | AK4: % PREVISTO | AL4: % concluída | AM4: % PREVISTO | AN4: % concluída | AO4: % PREVISTO | AP4: % concluída | AQ4: % PREVISTO | AR4: % concluída | AS4: % PREVISTO | AT4: % concluída | AU4: % PREVISTO | AV4: % concluída | AW4: % PREVISTO | AX4: % concluída | AY4: % PREVISTO | AZ4: % concluída | BA4: % PREVISTO | BB4: % concluída | BC4: % PREVISTO | BD4: % concluída | BE4: % PREVISTO | BF4: % concluída | BG4: % PREVISTO | BH4: % concluída | BI4: % PREVISTO | BJ4: % concluída | BK4: % PREVISTO | BL4: % concluída | BM4: % PREVISTO | BN4: % concluída | BO4: % PREVISTO | BP4: % concluída | BQ4: % PREVISTO | BR4: % concluída | BS4: % PREVISTO | BT4: % concluída | BU4: % PREVISTO | BV4: % concluída | BW4: % PREVISTO | BX4: % concluída | BY4: % PREVISTO | BZ4: % concluída | CA4: % PREVISTO | CB4: % concluída | CC4: % PREVISTO | CD4: % concluída | CE4: % PREVISTO | CF4: % concluída | CG4: % PREVISTO | CH4: % concluída | CI4: % PREVISTO | CJ4: % concluída | CK4: % PREVISTO | CL4: % concluída | CM4: % PREVISTO | CN4: % concluída | CO4: % PREVISTO | CP4: % concluída | CQ4: % PREVISTO | CR4: % concluída | CS4: % PREVISTO | CT4: % concluída | CU4: % PREVISTO | CV4: % concluída | CW4: % PREVISTO | CX4: % concluída | CY4: % PREVISTO | CZ4: % concluída | DA4: % PREVISTO | DB4: % concluída | DC4: % PREVISTO | DD4: % concluída | DE4: % PREVISTO | DF4: % concluída | DG4: % PREVISTO | DH4: % concluída | DI4: % PREVISTO | DJ4: % concluída | DK4: % PREVISTO | DL4: % concluída | DM4: % PREVISTO | DN4: % concluída | DO4: % PREVISTO | DP4: % concluída | DQ4: % PREVISTO | DR4: % concluída | DS4: % PREVISTO | DT4: % concluída | DU4: % PREVISTO | DV4: % concluída | DW4: % PREVISTO | DX4: % concluída | DY4: % PREVISTO | DZ4: % concluída | EA4: % PREVISTO | EB4: % concluída | EC4: % PREVISTO | ED4: % concluída | EE4: % PREVISTO | EF4: % concluída | EG4: % PREVISTO | EH4: % concluída | EI4: % PREVISTO | EJ4: % concluída | EK4: % PREVISTO | EL4: % concluída | EM4: % PREVISTO | EN4: % concluída | EO4: % PREVISTO | EP4: % concluída | EQ4: % PREVISTO | ER4: % concluída | ES4: % PREVISTO | ET4: % concluída | EU4: % PREVISTO | EV4: % concluída | EW4: % PREVISTO
A5: =_xlfn.XLOOKUP(DADOS!$B$3,DADOS!$D$2:$DI$2,DADOS!$D5:$DI5,"",0) -> 0.03 | B5: =_xlfn.XLOOKUP(DADOS!$B$3,DADOS!$E$112:$AS$112,DADOS!$E113:$AS113,"",0) -> 0.03 | C5: PLN_747_09_2025_R02_HOTEL QIU 2 -F4 | D5: 0.01 | E5: {=_xlfn.XLOOKUP(D$2,$D$112:$BF$112,$D113:BF113,0,0)} -> 0.01 | F5: 0.01 | G5: =_xlfn.XLOOKUP(F$2,$D$112:$AS$112,D113:AS113,0,0) -> 0.01 | H5: 0.02 | I5: =_xlfn.XLOOKUP(H$2,$D$112:$AS$112,D113:AS113,0,0) -> 0.02 | J5: 0.03 | K5: =_xlfn.XLOOKUP(J$2,$D$112:$AS$112,D113:AS113,0,0) -> 0.03 | M5: =_xlfn.XLOOKUP(L$2,$D$112:$AS$112,F113:AU113,0,0) -> 0.12 | O5: =_xlfn.XLOOKUP(N$2,$D$112:$AS$112,H113:AW113,0,0) -> 0.2 | Q5: =_xlfn.XLOOKUP(P$2,$D$112:$AS$112,J113:AY113,0,0) -> 0.26 | S5: =_xlfn.XLOOKUP(R$2,$D$112:$AS$112,L113:BA113,0,0) -> 0.34 | U5: =_xlfn.XLOOKUP(T$2,$D$112:$AS$112,N113:BC113,0,0) -> 0.44 | W5: =_xlfn.XLOOKUP(V$2,$D$112:$AS$112,P113:BE113,0,0) -> 0.52
A6: =_xlfn.XLOOKUP(DADOS!$B$3,DADOS!$D$2:$DI$2,DADOS!$D6:$DI6,"",0) -> 1 | B6: =_xlfn.XLOOKUP(DADOS!$B$3,DADOS!$E$112:$AS$112,DADOS!$E114:$AS114,"",0) -> 1 | C6: INICIO DO PROJETO - MOBILIZAÇÃO | E6: {=_xlfn.XLOOKUP(D$2,$D$112:$BF$112,$D114:BF114,0,0)} -> 1 | G6: =_xlfn.XLOOKUP(F$2,$D$112:$AS$112,D114:AS114,0,0) -> 1 | I6: =_xlfn.XLOOKUP(H$2,$D$112:$AS$112,D114:AS114,0,0) -> 1 | J6: 1 | K6: =_xlfn.XLOOKUP(J$2,$D$112:$AS$112,D114:AS114,0,0) -> 1 | M6: {=_xlfn.XLOOKUP(L$2,$D$112:$AS$112,$D$114:AS114,0,0)} -> 1 | O6: =_xlfn.XLOOKUP(N$2,$D$112:$AS$112,D114:AS114,0,0) -> 1 | Q6: =_xlfn.XLOOKUP(P$2,$D$112:$AS$112,D114:AS114,0,0) -> 1 | S6: =_xlfn.XLOOKUP(R$2,$D$112:$AS$112,D114:AS114,0,0) -> 1 | U6: =_xlfn.XLOOKUP(T$2,$D$112:$AS$112,D114:AS114,0,0) -> 1 | W6: =_xlfn.XLOOKUP(V$2,$D$112:$AS$112,D114:AS114,0,0) -> 1
A7: =_xlfn.XLOOKUP(DADOS!$B$3,DADOS!$D$2:$DI$2,DADOS!$D7:$DI7,"",0) -> 0.08 | B7: =_xlfn.XLOOKUP(DADOS!$B$3,DADOS!$E$112:$AS$112,DADOS!$E115:$AS115,"",0) -> 0.06 | C7: INSTALAÇÕES PROVISÓRIAS E CUSTO INDIRETO: | E7: {=_xlfn.XLOOKUP(D$2,$D$112:$BF$112,$D115:BF115,0,0)} -> 0.02 | G7: =_xlfn.XLOOKUP(F$2,$D$112:$AS$112,D115:AS115,0,0) -> 0.02 | I7: =_xlfn.XLOOKUP(H$2,$D$112:$AS$112,D115:AS115,0,0) -> 0.04 | J7: 0.08 | K7: =_xlfn.XLOOKUP(J$2,$D$112:$AS$112,D115:AS115,0,0) -> 0.06 | M7: =_xlfn.XLOOKUP(L$2,$D$112:$AS$112,F115:AU115,0,0) -> 0.15 | O7: =_xlfn.XLOOKUP(N$2,$D$112:$AS$112,D115:AS115,0,0) -> 0.13 | Q7: =_xlfn.XLOOKUP(P$2,$D$112:$AS$112,D115:AS115,0,0) -> 0.15 | S7: =_xlfn.XLOOKUP(R$2,$D$112:$AS$112,D115:AS115,0,0) -> 0.17 | U7: =_xlfn.XLOOKUP(T$2,$D$112:$AS$112,D115:AS115,0,0) -> 0.2 | W7: =_xlfn.XLOOKUP(V$2,$D$112:$AS$112,D115:AS115,0,0) -> 0.22
A8: =_xlfn.XLOOKUP(DADOS!$B$3,DADOS!$D$2:$DI$2,DADOS!$D8:$DI8,"",0) -> 0.02 | B8: =_xlfn.XLOOKUP(DADOS!$B$3,DADOS!$E$112:$AS$112,DADOS!$E116:$AS116,"",0) -> 0.05 | C8: 5º PAVIMENTO: | E8: {=_xlfn.XLOOKUP(D$2,$D$112:$BF$112,$D116:BF116,0,0)} -> 0.02 | G8: =_xlfn.XLOOKUP(F$2,$D$112:$AS$112,D116:AS116,0,0) -> 0.02 | I8: =_xlfn.XLOOKUP(H$2,$D$112:$AS$112,D116:AS116,0,0) -> 0.04 | J8: 0.02 | K8: =_xlfn.XLOOKUP(J$2,$D$112:$AS$112,D116:AS116,0,0) -> 0.05 | M8: =_xlfn.XLOOKUP(L$2,$D$112:$AS$112,F116:AU116,0,0) -> 0.46 | O8: =_xlfn.XLOOKUP(N$2,$D$112:$AS$112,D116:AS116,0,0) -> 0.36 | Q8: =_xlfn.XLOOKUP(P$2,$D$112:$AS$112,D116:AS116,0,0) -> 0.46 | S8: =_xlfn.XLOOKUP(R$2,$D$112:$AS$112,D116:AS116,0,0) -> 0.58 | U8: =_xlfn.XLOOKUP(T$2,$D$112:$AS$112,D116:AS116,0,0) -> 0.6 | W8: =_xlfn.XLOOKUP(V$2,$D$112:$AS$112,D116:AS116,0,0) -> 0.62
A9: =_xlfn.XLOOKUP(DADOS!$B$3,DADOS!$D$2:$DI$2,DADOS!$D9:$DI9,"",0) -> 0 | B9: =_xlfn.XLOOKUP(DADOS!$B$3,DADOS!$E$112:$AS$112,DADOS!$E117:$AS117,"",0) -> 0.81 | C9: ESGOTO: | E9: {=_xlfn.XLOOKUP(D$2,$D$112:$BF$112,$D117:BF117,0,0)} -> 0 | G9: =_xlfn.XLOOKUP(F$2,$D$112:$AS$112,D117:AS117,0,0) -> 0 | I9: =_xlfn.XLOOKUP(H$2,$D$112:$AS$112,D117:AS117,0,0) -> 0.65 | J9: 0 | K9: =_xlfn.XLOOKUP(J$2,$D$112:$AS$112,D117:AS117,0,0) -> 0.81 | M9: =_xlfn.XLOOKUP(L$2,$D$112:$AS$112,F117:AU117,0,0) -> 1 | O9: =_xlfn.XLOOKUP(N$2,$D$112:$AS$112,D117:AS117,0,0) -> 1 | Q9: =_xlfn.XLOOKUP(P$2,$D$112:$AS$112,D117:AS117,0,0) -> 1 | S9: =_xlfn.XLOOKUP(R$2,$D$112:$AS$112,D117:AS117,0,0) -> 1 | U9: =_xlfn.XLOOKUP(T$2,$D$112:$AS$112,D117:AS117,0,0) -> 1 | W9: =_xlfn.XLOOKUP(V$2,$D$112:$AS$112,D117:AS117,0,0) -> 1
A10: =_xlfn.XLOOKUP(DADOS!$B$3,DADOS!$D$2:$DI$2,DADOS!$D10:$DI10,"",0) -> 0.02 | B10: =_xlfn.XLOOKUP(DADOS!$B$3,DADOS!$E$112:$AS$112,DADOS!$E118:$AS118,"",0) -> 0.65 | C10: ÁGUA FRIA: | E10: {=_xlfn.XLOOKUP(D$2,$D$112:$BF$112,$D118:BF118,0,0)} -> 0.31 | G10: =_xlfn.XLOOKUP(F$2,$D$112:$AS$112,D118:AS118,0,0) -> 0.31 | I10: =_xlfn.XLOOKUP(H$2,$D$112:$AS$112,D118:AS118,0,0) -> 0.5 | J10: 0.02 | K10: =_xlfn.XLOOKUP(J$2,$D$112:$AS$112,D118:AS118,0,0) -> 0.65 | M10: =_xlfn.XLOOKUP(L$2,$D$112:$AS$112,F118:AU118,0,0) -> 1 | O10: =_xlfn.XLOOKUP(N$2,$D$112:$AS$112,D118:AS118,0,0) -> 1 | Q10: =_xlfn.XLOOKUP(P$2,$D$112:$AS$112,D118:AS118,0,0) -> 1 | S10: =_xlfn.XLOOKUP(R$2,$D$112:$AS$112,D118:AS118,0,0) -> 1 | U10: =_xlfn.XLOOKUP(T$2,$D$112:$AS$112,D118:AS118,0,0) -> 1 | W10: =_xlfn.XLOOKUP(V$2,$D$112:$AS$112,D118:AS118,0,0) -> 1
A11: =_xlfn.XLOOKUP(DADOS!$B$3,DADOS!$D$2:$DI$2,DADOS!$D11:$DI11,"",0) -> 0 | B11: =_xlfn.XLOOKUP(DADOS!$B$3,DADOS!$E$112:$AS$112,DADOS!$E119:$AS119,"",0) -> 0.3 | C11: ÁGUA QUENTE: | E11: {=_xlfn.XLOOKUP(D$2,$D$112:$BF$112,$D119:BF119,0,0)} -> 0 | G11: =_xlfn.XLOOKUP(F$2,$D$112:$AS$112,D119:AS119,0,0) -> 0 | I11: =_xlfn.XLOOKUP(H$2,$D$112:$AS$112,D119:AS119,0,0) -> 0.04 | J11: 0 | K11: =_xlfn.XLOOKUP(J$2,$D$112:$AS$112,D119:AS119,0,0) -> 0.3 | M11: =_xlfn.XLOOKUP(L$2,$D$112:$AS$112,F119:AU119,0,0) -> 0.91 | O11: =_xlfn.XLOOKUP(N$2,$D$112:$AS$112,D119:AS119,0,0) -> 0.8 | Q11: =_xlfn.XLOOKUP(P$2,$D$112:$AS$112,D119:AS119,0,0) -> 0.91 | S11: =_xlfn.XLOOKUP(R$2,$D$112:$AS$112,D119:AS119,0,0) -> 1 | U11: =_xlfn.XLOOKUP(T$2,$D$112:$AS$112,D119:AS119,0,0) -> 1 | W11: =_xlfn.XLOOKUP(V$2,$D$112:$AS$112,D119:AS119,0,0) -> 1
A12: =_xlfn.XLOOKUP(DADOS!$B$3,DADOS!$D$2:$DI$2,DADOS!$D12:$DI12,"",0) -> 0.01 | B12: =_xlfn.XLOOKUP(DADOS!$B$3,DADOS!$E$112:$AS$112,DADOS!$E120:$AS120,"",0) -> 0 | C12: AR CONDICIONADO: | E12: {=_xlfn.XLOOKUP(D$2,$D$112:$BF$112,$D120:BF120,0,0)} -> 0 | G12: =_xlfn.XLOOKUP(F$2,$D$112:$AS$112,D120:AS120,0,0) -> 0 | I12: =_xlfn.XLOOKUP(H$2,$D$112:$AS$112,D120:AS120,0,0) -> 0 | J12: 0.01 | K12: =_xlfn.XLOOKUP(J$2,$D$112:$AS$112,D120:AS120,0,0) -> 0 | M12: =_xlfn.XLOOKUP(L$2,$D$112:$AS$112,F120:AU120,0,0) -> 1 | O12: =_xlfn.XLOOKUP(N$2,$D$112:$AS$112,D120:AS120,0,0) -> 1 | Q12: =_xlfn.XLOOKUP(P$2,$D$112:$AS$112,D120:AS120,0,0) -> 1 | S12: =_xlfn.XLOOKUP(R$2,$D$112:$AS$112,D120:AS120,0,0) -> 1 | U12: =_xlfn.XLOOKUP(T$2,$D$112:$AS$112,D120:AS120,0,0) -> 1 | W12: =_xlfn.XLOOKUP(V$2,$D$112:$AS$112,D120:AS120,0,0) -> 1
A13: =_xlfn.XLOOKUP(DADOS!$B$3,DADOS!$D$2:$DI$2,DADOS!$D13:$DI13,"",0) -> 0.06 | B13: =_xlfn.XLOOKUP(DADOS!$B$3,DADOS!$E$112:$AS$112,DADOS!$E121:$AS121,"",0) -> 0 | C13: ELÉTRICA: | E13: {=_xlfn.XLOOKUP(D$2,$D$112:$BF$112,$D121:BF121,0,0)} -> 0 | G13: =_xlfn.XLOOKUP(F$2,$D$112:$AS$112,D121:AS121,0,0) -> 0 | I13: =_xlfn.XLOOKUP(H$2,$D$112:$AS$112,D121:AS121,0,0) -> 0 | J13: 0.06 | K13: =_xlfn.XLOOKUP(J$2,$D$112:$AS$112,D121:AS121,0,0) -> 0 | M13: =_xlfn.XLOOKUP(L$2,$D$112:$AS$112,F121:AU121,0,0) -> 0.46 | O13: =_xlfn.XLOOKUP(N$2,$D$112:$AS$112,D121:AS121,0,0) -> 0.37 | Q13: =_xlfn.XLOOKUP(P$2,$D$112:$AS$112,D121:AS121,0,0) -> 0.46 | S13: =_xlfn.XLOOKUP(R$2,$D$112:$AS$112,D121:AS121,0,0) -> 0.75 | U13: =_xlfn.XLOOKUP(T$2,$D$112:$AS$112,D121:AS121,0,0) -> 0.75 | W13: =_xlfn.XLOOKUP(V$2,$D$112:$AS$112,D121:AS121,0,0) -> 0.75
A14: =_xlfn.XLOOKUP(DADOS!$B$3,DADOS!$D$2:$DI$2,DADOS!$D14:$DI14,"",0) -> 0.02 | B14: =_xlfn.XLOOKUP(DADOS!$B$3,DADOS!$E$112:$AS$112,DADOS!$E122:$AS122,"",0) -> 0 | C14: TEL, CFTV E DADOS: | E14: {=_xlfn.XLOOKUP(D$2,$D$112:$BF$112,$D122:BF122,0,0)} -> 0 | G14: =_xlfn.XLOOKUP(F$2,$D$112:$AS$112,D122:AS122,0,0) -> 0 | I14: =_xlfn.XLOOKUP(H$2,$D$112:$AS$112,D122:AS122,0,0) -> 0 | J14: 0.02 | K14: =_xlfn.XLOOKUP(J$2,$D$112:$AS$112,D122:AS122,0,0) -> 0 | M14: =_xlfn.XLOOKUP(L$2,$D$112:$AS$112,F122:AU122,0,0) -> 0.72 | O14: =_xlfn.XLOOKUP(N$2,$D$112:$AS$112,D122:AS122,0,0) -> 0.39 | Q14: =_xlfn.XLOOKUP(P$2,$D$112:$AS$112,D122:AS122,0,0) -> 0.72 | S14: =_xlfn.XLOOKUP(R$2,$D$112:$AS$112,D122:AS122,0,0) -> 0.91 | U14: =_xlfn.XLOOKUP(T$2,$D$112:$AS$112,D122:AS122,0,0) -> 0.91 | W14: =_xlfn.XLOOKUP(V$2,$D$112:$AS$112,D122:AS122,0,0) -> 0.91
A15: =_xlfn.XLOOKUP(DADOS!$B$3,DADOS!$D$2:$DI$2,DADOS!$D15:$DI15,"",0) -> 0 | B15: =_xlfn.XLOOKUP(DADOS!$B$3,DADOS!$E$112:$AS$112,DADOS!$E123:$AS123,"",0) -> 0 | C15: PCI: | E15: {=_xlfn.XLOOKUP(D$2,$D$112:$BF$112,$D123:BF123,0,0)} -> 0 | G15: =_xlfn.XLOOKUP(F$2,$D$112:$AS$112,D123:AS123,0,0) -> 0 | I15: =_xlfn.XLOOKUP(H$2,$D$112:$AS$112,D123:AS123,0,0) -> 0 | J15: 0 | K15: =_xlfn.XLOOKUP(J$2,$D$112:$AS$112,D123:AS123,0,0) -> 0 | M15: =_xlfn.XLOOKUP(L$2,$D$112:$AS$112,F123:AU123,0,0) -> 0.55 | O15: =_xlfn.XLOOKUP(N$2,$D$112:$AS$112,D123:AS123,0,0) -> 0.12 | Q15: =_xlfn.XLOOKUP(P$2,$D$112:$AS$112,D123:AS123,0,0) -> 0.55 | S15: =_xlfn.XLOOKUP(R$2,$D$112:$AS$112,D123:AS123,0,0) -> 0.74 | U15: =_xlfn.XLOOKUP(T$2,$D$112:$AS$112,D123:AS123,0,0) -> 0.76 | W15: =_xlfn.XLOOKUP(V$2,$D$112:$AS$112,D123:AS123,0,0) -> 0.76
A16: =_xlfn.XLOOKUP(DADOS!$B$3,DADOS!$D$2:$DI$2,DADOS!$D16:$DI16,"",0) -> 0 | B16: =_xlfn.XLOOKUP(DADOS!$B$3,DADOS!$E$112:$AS$112,DADOS!$E124:$AS124,"",0) -> 0 | C16: IMPERMEAB.: | E16: {=_xlfn.XLOOKUP(D$2,$D$112:$BF$112,$D124:BF124,0,0)} -> 0 | G16: =_xlfn.XLOOKUP(F$2,$D$112:$AS$112,D124:AS124,0,0) -> 0 | I16: =_xlfn.XLOOKUP(H$2,$D$112:$AS$112,D124:AS124,0,0) -> 0 | J16: 0 | K16: =_xlfn.XLOOKUP(J$2,$D$112:$AS$112,D124:AS124,0,0) -> 0 | M16: =_xlfn.XLOOKUP(L$2,$D$112:$AS$112,F124:AU124,0,0) -> 0 | O16: =_xlfn.XLOOKUP(N$2,$D$112:$AS$112,D124:AS124,0,0) -> 0 | Q16: =_xlfn.XLOOKUP(P$2,$D$112:$AS$112,D124:AS124,0,0) -> 0 | S16: =_xlfn.XLOOKUP(R$2,$D$112:$AS$112,D124:AS124,0,0) -> 0.29 | U16: =_xlfn.XLOOKUP(T$2,$D$112:$AS$112,D124:AS124,0,0) -> 0.74 | W16: =_xlfn.XLOOKUP(V$2,$D$112:$AS$112,D124:AS124,0,0) -> 1
A17: =_xlfn.XLOOKUP(DADOS!$B$3,DADOS!$D$2:$DI$2,DADOS!$D17:$DI17,"",0) -> 0.07 | B17: =_xlfn.XLOOKUP(DADOS!$B$3,DADOS!$E$112:$AS$112,DADOS!$E125:$AS125,"",0) -> 0 | C17: REVEST. MASSA: | E17: {=_xlfn.XLOOKUP(D$2,$D$112:$BF$112,$D125:BF125,0,0)} -> 0 | G17: =_xlfn.XLOOKUP(F$2,$D$112:$AS$112,D125:AS125,0,0) -> 0 | I17: =_xlfn.XLOOKUP(H$2,$D$112:$AS$112,D125:AS125,0,0) -> 0 | J17: 0.07 | K17: =_xlfn.XLOOKUP(J$2,$D$112:$AS$112,D125:AS125,0,0) -> 0 | M17: =_xlfn.XLOOKUP(L$2,$D$112:$AS$112,F125:AU125,0,0) -> 0.63 | O17: =_xlfn.XLOOKUP(N$2,$D$112:$AS$112,D125:AS125,0,0) -> 0.42 | Q17: =_xlfn.XLOOKUP(P$2,$D$112:$AS$112,D125:AS125,0,0) -> 0.63 | S17: =_xlfn.XLOOKUP(R$2,$D$112:$AS$112,D125:AS125,0,0) -> 0.82 | U17: =_xlfn.XLOOKUP(T$2,$D$112:$AS$112,D125:AS125,0,0) -> 1 | W17: =_xlfn.XLOOKUP(V$2,$D$112:$AS$112,D125:AS125,0,0) -> 1
A18: =_xlfn.XLOOKUP(DADOS!$B$3,DADOS!$D$2:$DI$2,DADOS!$D18:$DI18,"",0) -> 0 | B18: =_xlfn.XLOOKUP(DADOS!$B$3,DADOS!$E$112:$AS$112,DADOS!$E126:$AS126,"",0) -> 0 | C18: REVEST. CERÂMICO: | E18: {=_xlfn.XLOOKUP(D$2,$D$112:$BF$112,$D126:BF126,0,0)} -> 0 | G18: =_xlfn.XLOOKUP(F$2,$D$112:$AS$112,D126:AS126,0,0) -> 0 | I18: =_xlfn.XLOOKUP(H$2,$D$112:$AS$112,D126:AS126,0,0) -> 0 | J18: 0 | K18: =_xlfn.XLOOKUP(J$2,$D$112:$AS$112,D126:AS126,0,0) -> 0 | M18: =_xlfn.XLOOKUP(L$2,$D$112:$AS$112,F126:AU126,0,0) -> 0 | O18: =_xlfn.XLOOKUP(N$2,$D$112:$AS$112,D126:AS126,0,0) -> 0 | Q18: =_xlfn.XLOOKUP(P$2,$D$112:$AS$112,D126:AS126,0,0) -> 0 | S18: =_xlfn.XLOOKUP(R$2,$D$112:$AS$112,D126:AS126,0,0) -> 0 | U18: =_xlfn.XLOOKUP(T$2,$D$112:$AS$112,D126:AS126,0,0) -> 0 | W18: =_xlfn.XLOOKUP(V$2,$D$112:$AS$112,D126:AS126,0,0) -> 0.11
... A99: =_xlfn.XLOOKUP(DADOS!$B$3,DADOS!$D$2:$DI$2,DADOS!$D99:$DI99,"",0) -> 0 | B99: =_xlfn.XLOOKUP(DADOS!$B$3,DADOS!$E$112:$AS$112,DADOS!$E207:$AS207,"",0) -> 0 | C99: FIM DO PROJETO - DESMOBILIZAÇÃO | E99: {=_xlfn.XLOOKUP(D$2,$D$112:$BF$112,$D207:BF207,0,0)} -> 0 | G99: =_xlfn.XLOOKUP(F$2,$D$112:$AS$112,D207:AS207,0,0) -> 0 | I99: =_xlfn.XLOOKUP(H$2,$D$112:$AS$112,D207:AS207,0,0) -> 0 | J99: 0 | K99: =_xlfn.XLOOKUP(J$2,$D$112:$AS$112,D207:AS207,0,0) -> 0 | M99: =_xlfn.XLOOKUP(L$2,$D$112:$AS$112,F207:AU207,0,0) -> 0 | O99: =_xlfn.XLOOKUP(N$2,$D$112:$AS$112,D207:AS207,0,0) -> 0 | Q99: =_xlfn.XLOOKUP(P$2,$D$112:$AS$112,D207:AS207,0,0) -> 0 | S99: =_xlfn.XLOOKUP(R$2,$D$112:$AS$112,D207:AS207,0,0) -> 0 | U99: =_xlfn.XLOOKUP(T$2,$D$112:$AS$112,D207:AS207,0,0) -> 0 | W99: =_xlfn.XLOOKUP(V$2,$D$112:$AS$112,D207:AS207,0,0) -> 0
E101: JANEIRO | F101: FEVEREIRO | J101: MARÇO | N101: ABRIL | S101: MAIO | W101: JUNHO | AA101: JULHO | AF101: AGOSTO | AJ101: SETEMBRO | AN101: OUTUBRO | AS101: NOVEMBRO | AW101: DEZEMBRO
D102: 0º | E102: 1º | F102: 2º | G102: 3º | H102: 4º | I102: 5º | J102: 6º | K102: 7º | L102: 8º | M102: 9º | N102: 10º | O102: 11º | P102: 12º | Q102: 13º | R102: 14º | S102: 15º | T102: 16º | U102: 17º | V102: 18º | W102: 19º | X102: 20º | Y102: 21º | Z102: 22º | AA102: 23º | AB102: 24º | AC102: 25º | AD102: 26º | AE102: 27º | AF102: 28º | AG102: 29º | AH102: 30º | AI102: 31º | AJ102: 32º | AK102: 33º | AL102: 34º | AM102: 35º | AN102: 36º | AO102: 37º | AP102: 38º | AQ102: 39º | AR102: 40º | AS102: 41º | AT102: 42º | AU102: 43º | AV102: 44º | AW102: 45º | AX102: 46º | AY102: 47º | AZ102: 48º | BA102: 49º | BB102: 50º | BC102: 51º | BD102: 52º | BE102: 53º | BF102: 54º | BG102: 55º | BH102: 56º | BI102: 57º | BJ102: 58º | BK102: 59º | BL102: 60º | BM102: 61º | BN102: 62º | BO102: 63º | BP102: 64º | BQ102: 65º
C103: EVOLUÇÃO PREVISTA SEMANAL | D103: 0 | E103: =E113 -> 0.01 | F103: =F113-E113 -> 0 | G103: =G113-F113 -> 0.01 | H103: =H113-G113 -> 0.01 | I103: =I113-H113 -> 0.03 | J103: =J113-I113 -> 0.03 | K103: =K113-J113 -> 0.03 | L103: =L113-K113 -> 0.03 | M103: =M113-L113 -> 0.02 | ... BQ103: =BQ113-BP113 -> 0 | BR103: =ROUND(AVERAGE(E103:H103),4) -> 0.0075 | BS103: % PREVISTO | BT103: =_xlfn.XLOOKUP($B$3,$E$102:$BQ$102,$E$104:$BQ$104,,0) -> 0.03
C104: EVOLUÇÃO PREVISTA ACUMULADA %: | D104: 0 | E104: =E103 -> 0.01 | F104: =E104+F103 -> 0.01 | G104: =F104+G103 -> 0.02 | H104: =G104+H103 -> 0.03 | I104: =H104+I103 -> 0.06 | J104: =I104+J103 -> 0.09 | K104: =J104+K103 -> 0.12 | L104: =K104+L103 -> 0.15 | M104: =L104+M103 -> 0.17 | ... BQ104: =BP104+BQ103 -> 0 | BS104: % REALIZADO | BT104: =_xlfn.XLOOKUP($B$3,$E$102:$BQ$102,$E$107:$BQ$107,,0) -> 0.03
C106: EVOLUÇÃO REAL SEMANAL | D106: 0 | E106: =D5 -> 0.01 | F106: =F5-D5 -> 0 | G106: =H5-F5 -> 0.01 | H106: =J5-H5 -> 0.01 | I106: =L5-J5 -> -0.03 | J106: =N5-L5 -> 0 | K106: =P5-N5 -> 0 | L106: =R5-P5 -> 0 | M106: =T5-R5 -> 0 | N106: =V5-T5 -> 0 | O106: =X5-V5 -> 0 | P106: =Z5-X5 -> 0 | Q106: =AA5-Y5 -> 0 | R106: =AB5-Z5 -> 0 | S106: =AC5-AA5 -> 0 | T106: =AD5-AB5 -> 0 | U106: =AE5-AC5 -> 0 | V106: =AF5-AD5 -> 0 | W106: =AG5-AE5 -> 0 | ... AC106: =AM5-AK5 -> 0 | BR106: =ROUND(AVERAGE(E106:H106),4) -> 0.0075
C107: EVOLUÇÃO REAL ACUMULADA %: | D107: 0 | E107: =E106 -> 0.01 | F107: =E107+F106 -> 0.01 | G107: =F107+G106 -> 0.02 | H107: =G107+H106 -> 0.03 | I107: =H107+I106 -> 0 | J107: =I107+J106 -> 0 | K107: =J107+K106 -> 0 | L107: =K107+L106 -> 0 | M107: =L107+M106 -> 0 | ... AC107: =AB107+AC106 -> 0
C111: CRONOGRAMA FÍSICO FINANCEIRO R00
C112: Descrição | D112: 0º | E112: 1º | F112: 2º | G112: 3º | H112: 4º | I112: 5º | J112: 6º | K112: 7º | L112: 8º | M112: 9º | N112: 10º | O112: 11º | P112: 12º | Q112: 13º | R112: 14º | S112: 15º | T112: 16º | U112: 17º | V112: 18º | W112: 19º | X112: 20º | Y112: 21º | Z112: 22º | AA112: 23º | AB112: 24º | AC112: 25º | AD112: 26º | AE112: 27º | AF112: 28º | AG112: 29º | AH112: 30º | AI112: 31º | AJ112: 32º | AK112: 33º | AL112: 34º | AM112: 35º | AN112: 36º | AO112: 37º | AP112: 38º | AQ112: 39º | AR112: 40º | AS112: 41º | AT112: 42º | AU112: 43º | AV112: 44º | AW112: 45º | AX112: 46º | AY112: 47º | AZ112: 48º | BA112: 49º | BB112: 50º | BC112: 51º | BD112: 52º | BE112: 53º | BF112: 54º
C113: PLN_747_09_2025_R02_HOTEL QIU 2 -F4 | E113: 0.01 | F113: 0.01 | G113: 0.02 | H113: 0.03 | I113: 0.06 | J113: 0.09 | K113: 0.12 | L113: 0.15 | M113: 0.17 | N113: 0.2 | O113: 0.23 | P113: 0.24 | Q113: 0.26 | R113: 0.28 | S113: 0.3 | T113: 0.34 | U113: 0.37 | V113: 0.41 | W113: 0.44 | X113: 0.46 | Y113: 0.48 | Z113: 0.52 | AA113: 0.55 | AB113: 0.57 | AC113: 0.59 | AD113: 0.62 | AE113: 0.64 | AF113: 0.67 | AG113: 0.69 | AH113: 0.72 | AI113: 0.74 | AJ113: 0.77 | AK113: 0.78 | AL113: 0.81 | AM113: 0.83 | AN113: 0.85 | AO113: 0.87 | AP113: 0.88 | AQ113: 0.89 | AR113: 0.91 | AS113: 0.92 | AT113: 0.93 | AU113: 0.95 | AV113: 0.98 | AW113: 0.99 | AX113: 0.99 | AY113: 1 | AZ113: 1 | BA113: 1 | BB113: 1 | BC113: 1 | BD113: 1 | BE113: 1 | BF113: 1
C114: INICIO DO PROJETO - MOBILIZAÇÃO | E114: 1 | F114: 1 | G114: 1 | H114: 1 | I114: 1 | J114: 1 | K114: 1 | L114: 1 | M114: 1 | N114: 1 | O114: 1 | P114: 1 | Q114: 1 | R114: 1 | S114: 1 | T114: 1 | U114: 1 | V114: 1 | W114: 1 | X114: 1 | Y114: 1 | Z114: 1 | AA114: 1 | AB114: 1 | AC114: 1 | AD114: 1 | AE114: 1 | AF114: 1 | AG114: 1 | AH114: 1 | AI114: 1 | AJ114: 1 | AK114: 1 | AL114: 1 | AM114: 1 | AN114: 1 | AO114: 1 | AP114: 1 | AQ114: 1 | AR114: 1 | AS114: 1 | AT114: 1 | AU114: 1 | AV114: 1 | AW114: 1 | AX114: 1 | AY114: 1 | AZ114: 1 | BA114: 1 | BB114: 1 | BC114: 1 | BD114: 1 | BE114: 1 | BF114: 1
C115: INSTALAÇÕES PROVISÓRIAS E CUSTO INDIRETO: | E115: 0.02 | F115: 0.02 | G115: 0.04 | H115: 0.06 | I115: 0.11 | J115: 0.13 | K115: 0.15 | L115: 0.17 | M115: 0.2 | N115: 0.22 | O115: 0.24 | P115: 0.26 | Q115: 0.28 | R115: 0.3 | S115: 0.32 | T115: 0.34 | U115: 0.36 | V115: 0.38 | W115: 0.41 | X115: 0.43 | Y115: 0.45 | Z115: 0.47 | AA115: 0.49 | AB115: 0.51 | AC115: 0.53 | AD115: 0.56 | AE115: 0.58 | AF115: 0.6 | AG115: 0.62 | AH115: 0.64 | AI115: 0.67 | AJ115: 0.69 | AK115: 0.71 | AL115: 0.73 | AM115: 0.76 | AN115: 0.78 | AO115: 0.8 | AP115: 0.82 | AQ115: 0.84 | AR115: 0.87 | AS115: 0.89 | AT115: 0.91 | AU115: 0.93 | AV115: 0.96 | AW115: 0.98 | AX115: 0.98 | AY115: 1 | AZ115: 1 | BA115: 1 | BB115: 1 | BC115: 1 | BD115: 1 | BE115: 1 | BF115: 1
C116: 5º PAVIMENTO: | E116: 0.02 | F116: 0.02 | G116: 0.04 | H116: 0.05 | I116: 0.24 | J116: 0.36 | K116: 0.46 | L116: 0.58 | M116: 0.6 | N116: 0.62 | O116: 0.64 | P116: 0.64 | Q116: 0.65 | R116: 0.68 | S116: 0.7 | T116: 0.76 | U116: 0.86 | V116: 0.95 | W116: 1 | X116: 1 | Y116: 1 | Z116: 1 | AA116: 1 | AB116: 1 | AC116: 1 | AD116: 1 | AE116: 1 | AF116: 1 | AG116: 1 | AH116: 1 | AI116: 1 | AJ116: 1 | AK116: 1 | AL116: 1 | AM116: 1 | AN116: 1 | AO116: 1 | AP116: 1 | AQ116: 1 | AR116: 1 | AS116: 1 | AT116: 1 | AU116: 1 | AV116: 1 | AW116: 1 | AX116: 1 | AY116: 1 | AZ116: 1 | BA116: 1 | BB116: 1 | BC116: 1 | BD116: 1 | BE116: 1 | BF116: 1
C117: ESGOTO: | E117: 0 | F117: 0 | G117: 0.65 | H117: 0.81 | I117: 1 | J117: 1 | K117: 1 | L117: 1 | M117: 1 | N117: 1 | O117: 1 | P117: 1 | Q117: 1 | R117: 1 | S117: 1 | T117: 1 | U117: 1 | V117: 1 | W117: 1 | X117: 1 | Y117: 1 | Z117: 1 | AA117: 1 | AB117: 1 | AC117: 1 | AD117: 1 | AE117: 1 | AF117: 1 | AG117: 1 | AH117: 1 | AI117: 1 | AJ117: 1 | AK117: 1 | AL117: 1 | AM117: 1 | AN117: 1 | AO117: 1 | AP117: 1 | AQ117: 1 | AR117: 1 | AS117: 1 | AT117: 1 | AU117: 1 | AV117: 1 | AW117: 1 | AX117: 1 | AY117: 1 | AZ117: 1 | BA117: 1 | BB117: 1 | BC117: 1 | BD117: 1 | BE117: 1 | BF117: 1
C118: ÁGUA FRIA: | E118: 0.31 | F118: 0.31 | G118: 0.5 | H118: 0.65 | I118: 0.95 | J118: 1 | K118: 1 | L118: 1 | M118: 1 | N118: 1 | O118: 1 | P118: 1 | Q118: 1 | R118: 1 | S118: 1 | T118: 1 | U118: 1 | V118: 1 | W118: 1 | X118: 1 | Y118: 1 | Z118: 1 | AA118: 1 | AB118: 1 | AC118: 1 | AD118: 1 | AE118: 1 | AF118: 1 | AG118: 1 | AH118: 1 | AI118: 1 | AJ118: 1 | AK118: 1 | AL118: 1 | AM118: 1 | AN118: 1 | AO118: 1 | AP118: 1 | AQ118: 1 | AR118: 1 | AS118: 1 | AT118: 1 | AU118: 1 | AV118: 1 | AW118: 1 | AX118: 1 | AY118: 1 | AZ118: 1 | BA118: 1 | BB118: 1 | BC118: 1 | BD118: 1 | BE118: 1 | BF118: 1
C119: ÁGUA QUENTE: | E119: 0 | F119: 0 | G119: 0.04 | H119: 0.3 | I119: 0.68 | J119: 0.8 | K119: 0.91 | L119: 1 | M119: 1 | N119: 1 | O119: 1 | P119: 1 | Q119: 1 | R119: 1 | S119: 1 | T119: 1 | U119: 1 | V119: 1 | W119: 1 | X119: 1 | Y119: 1 | Z119: 1 | AA119: 1 | AB119: 1 | AC119: 1 | AD119: 1 | AE119: 1 | AF119: 1 | AG119: 1 | AH119: 1 | AI119: 1 | AJ119: 1 | AK119: 1 | AL119: 1 | AM119: 1 | AN119: 1 | AO119: 1 | AP119: 1 | AQ119: 1 | AR119: 1 | AS119: 1 | AT119: 1 | AU119: 1 | AV119: 1 | AW119: 1 | AX119: 1 | AY119: 1 | AZ119: 1 | BA119: 1 | BB119: 1 | BC119: 1 | BD119: 1 | BE119: 1 | BF119: 1
C120: AR CONDICIONADO: | E120: 0 | F120: 0 | G120: 0 | H120: 0 | I120: 0.51 | J120: 1 | K120: 1 | L120: 1 | M120: 1 | N120: 1 | O120: 1 | P120: 1 | Q120: 1 | R120: 1 | S120: 1 | T120: 1 | U120: 1 | V120: 1 | W120: 1 | X120: 1 | Y120: 1 | Z120: 1 | AA120: 1 | AB120: 1 | AC120: 1 | AD120: 1 | AE120: 1 | AF120: 1 | AG120: 1 | AH120: 1 | AI120: 1 | AJ120: 1 | AK120: 1 | AL120: 1 | AM120: 1 | AN120: 1 | AO120: 1 | AP120: 1 | AQ120: 1 | AR120: 1 | AS120: 1 | AT120: 1 | AU120: 1 | AV120: 1 | AW120: 1 | AX120: 1 | AY120: 1 | AZ120: 1 | BA120: 1 | BB120: 1 | BC120: 1 | BD120: 1 | BE120: 1 | BF120: 1
C121: ELÉTRICA: | E121: 0 | F121: 0 | G121: 0 | H121: 0 | I121: 0.16 | J121: 0.37 | K121: 0.46 | L121: 0.75 | M121: 0.75 | N121: 0.75 | O121: 0.75 | P121: 0.75 | Q121: 0.75 | R121: 0.75 | S121: 0.75 | T121: 0.75 | U121: 0.75 | V121: 1 | W121: 1 | X121: 1 | Y121: 1 | Z121: 1 | AA121: 1 | AB121: 1 | AC121: 1 | AD121: 1 | AE121: 1 | AF121: 1 | AG121: 1 | AH121: 1 | AI121: 1 | AJ121: 1 | AK121: 1 | AL121: 1 | AM121: 1 | AN121: 1 | AO121: 1 | AP121: 1 | AQ121: 1 | AR121: 1 | AS121: 1 | AT121: 1 | AU121: 1 | AV121: 1 | AW121: 1 | AX121: 1 | AY121: 1 | AZ121: 1 | BA121: 1 | BB121: 1 | BC121: 1 | BD121: 1 | BE121: 1 | BF121: 1
C122: TEL, CFTV E DADOS: | E122: 0 | F122: 0 | G122: 0 | H122: 0 | I122: 0.25 | J122: 0.39 | K122: 0.72 | L122: 0.91 | M122: 0.91 | N122: 0.91 | O122: 0.91 | P122: 0.91 | Q122: 0.91 | R122: 0.91 | S122: 0.91 | T122: 0.91 | U122: 0.94 | V122: 1 | W122: 1 | X122: 1 | Y122: 1 | Z122: 1 | AA122: 1 | AB122: 1 | AC122: 1 | AD122: 1 | AE122: 1 | AF122: 1 | AG122: 1 | AH122: 1 | AI122: 1 | AJ122: 1 | AK122: 1 | AL122: 1 | AM122: 1 | AN122: 1 | AO122: 1 | AP122: 1 | AQ122: 1 | AR122: 1 | AS122: 1 | AT122: 1 | AU122: 1 | AV122: 1 | AW122: 1 | AX122: 1 | AY122: 1 | AZ122: 1 | BA122: 1 | BB122: 1 | BC122: 1 | BD122: 1 | BE122: 1 | BF122: 1
C123: PCI: | E123: 0 | F123: 0 | G123: 0 | H123: 0 | I123: 0 | J123: 0.12 | K123: 0.55 | L123: 0.74 | M123: 0.76 | N123: 0.76 | O123: 0.76 | P123: 0.76 | Q123: 0.76 | R123: 0.76 | S123: 0.76 | T123: 0.76 | U123: 0.76 | V123: 0.81 | W123: 1 | X123: 1 | Y123: 1 | Z123: 1 | AA123: 1 | AB123: 1 | AC123: 1 | AD123: 1 | AE123: 1 | AF123: 1 | AG123: 1 | AH123: 1 | AI123: 1 | AJ123: 1 | AK123: 1 | AL123: 1 | AM123: 1 | AN123: 1 | AO123: 1 | AP123: 1 | AQ123: 1 | AR123: 1 | AS123: 1 | AT123: 1 | AU123: 1 | AV123: 1 | AW123: 1 | AX123: 1 | AY123: 1 | AZ123: 1 | BA123: 1 | BB123: 1 | BC123: 1 | BD123: 1 | BE123: 1 | BF123: 1
C124: IMPERMEABILIZAÇÕES: | E124: 0 | F124: 0 | G124: 0 | H124: 0 | I124: 0 | J124: 0 | K124: 0 | L124: 0.29 | M124: 0.74 | N124: 1 | O124: 1 | P124: 1 | Q124: 1 | R124: 1 | S124: 1 | T124: 1 | U124: 1 | V124: 1 | W124: 1 | X124: 1 | Y124: 1 | Z124: 1 | AA124: 1 | AB124: 1 | AC124: 1 | AD124: 1 | AE124: 1 | AF124: 1 | AG124: 1 | AH124: 1 | AI124: 1 | AJ124: 1 | AK124: 1 | AL124: 1 | AM124: 1 | AN124: 1 | AO124: 1 | AP124: 1 | AQ124: 1 | AR124: 1 | AS124: 1 | AT124: 1 | AU124: 1 | AV124: 1 | AW124: 1 | AX124: 1 | AY124: 1 | AZ124: 1 | BA124: 1 | BB124: 1 | BC124: 1 | BD124: 1 | BE124: 1 | BF124: 1
... C207: FIM DO PROJETO - DESMOBILIZAÇÃO | E207: 0 | F207: 0 | G207: 0 | H207: 0 | I207: 0 | J207: 0 | K207: 0 | L207: 0 | M207: 0 | N207: 0 | O207: 0 | P207: 0 | Q207: 0 | R207: 0 | S207: 0 | T207: 0 | U207: 0 | V207: 0 | W207: 0 | X207: 0 | Y207: 0 | Z207: 0 | AA207: 0 | AB207: 0 | AC207: 0 | AD207: 0 | AE207: 0 | AF207: 0 | AG207: 0 | AH207: 0 | AI207: 0 | AJ207: 0 | AK207: 0 | AL207: 0 | AM207: 0 | AN207: 0 | AO207: 0 | AP207: 0 | AQ207: 0 | AR207: 0 | AS207: 0 | AT207: 0 | AU207: 0 | AV207: 0 | AW207: 0 | AX207: 0 | AY207: 1 | AZ207: 1 | BA207: 1 | BB207: 1 | BC207: 1 | BD207: 1 | BE207: 1 | BF207: 1
D210: REAL | E210: PREV
...

Sheet PMO PREV
E3: PERMANENCIA DE MÃO DE OBRA | S3: OBRA: | T3: DPW - LANES 05 E 09
E4: Julio Ferraz Projetos e Obras | S4: LOCAL: | T4: SANTOS - SP
E5: ANEXO "C" | S5: CLIENTE: | T5: DP WORLD
E6: R00 | K6: INÍCIO: | L6: 44984 | T6: TÉRMINO: | U6: 45131
B10: ITEM | C10: DESCRIÇÃO | E10: MÊS | F10: 1 | J10: 2 | N10: 3 | R10: 4 | V10: 5 | Z10: 6 | AD10: 7 | AH10: 8 | AL10: 9 | AP10: 10 | AT10: 11 | AX10: 12 | BB10: 13 | BF10: 14 | BJ10: 15 | BN10: 16 | BR10: 17 | BV10: 18 | BZ10: 19 | CD10: 19
E11: Semana | F11: 1 | G11: 2 | H11: 3 | I11: 4 | J11: 5 | K11: 6 | L11: 7 | M11: 8 | N11: 9 | O11: 10 | P11: 11 | Q11: 12 | R11: 13 | S11: 14 | T11: 15 | U11: 16 | V11: 17 | W11: 18 | X11: 19 | Y11: 20 | Z11: 21 | AA11: 22 | AB11: 23 | AC11: 24 | AD11: 25 | AE11: 26 | AF11: 27 | AG11: 28 | AH11: 29 | AI11: 30 | AJ11: 31 | AK11: 32 | AL11: 33 | AM11: 34 | AN11: 35 | AO11: 36 | AP11: 37 | AQ11: 38 | AR11: 39 | AS11: 40 | AT11: 41 | AU11: 42 | AV11: 43 | AW11: 44 | AX11: 45 | AY11: 46 | AZ11: 47 | BA11: 48 | BB11: 49 | BC11: 50 | BD11: 51 | BE11: 52 | BF11: 53 | BG11: 54 | BH11: 55 | BI11: 56 | BJ11: 57 | BK11: 58 | BL11: 59 | BM11: 60 | BN11: 61 | BO11: 62 | BP11: 63 | BQ11: 64 | BR11: 65 | BS11: 66 | BT11: 67 | BU11: 68 | BV11: 69 | BW11: 70 | BX11: 71 | BY11: 72 | BZ11: 73 | CA11: 74 | CB11: 75 | CC11: 76 | CD11: 77 | CE11: 78 | CF11: 79 | CG11: 80
B12: 1 | C12: INDIRETA PREVISTA | F12: =AVERAGE(F52:I52) -> 3.6306818 | J12: =AVERAGE(J52:M52) -> 11.022727 | N12: =AVERAGE(N52:Q52) -> 11.042614 | R12: =AVERAGE(R52:U52) -> 1.5056818 | V12: =AVERAGE(V52:Y52) -> 0 | Z12: =AVERAGE(Z52:AC52) -> 0 | AD12: =AVERAGE(AD52:AG52) -> 0 | AH12: =AVERAGE(AH52:AK52) -> 0 | AL12: =AVERAGE(AL52:AO52) -> 0 | AP12: =AVERAGE(AP52:AS52) -> 0 | AT12: =AVERAGE(AT52:AW52) -> 0 | AX12: =AVERAGE(AX52:BA52) -> 0 | BB12: =AVERAGE(BB52:BE52) -> 0 | BF12: =AVERAGE(BF52:BI52) -> 0 | BJ12: =AVERAGE(BJ52:BM52) -> 0 | BN12: =AVERAGE(BN52:BQ52) -> 0 | BR12: =AVERAGE(BR52:BU52) -> 0 | BV12: =AVERAGE(BV52:BY52) -> 0 | BZ12: =AVERAGE(BZ52:CC52) -> 0 | CD12: =AVERAGE(CD52:CG52) -> 0
B13: 1.01 | C13: Engenheiro | D13: =IFERROR(E13/$E$51,"") | E13: =IFERROR(AVERAGE(F13:CG13),"")
B14: 1.02 | C14: Técnico de Segurança do Trabalho | D14: =IFERROR(E14/$E$51,"") | E14: =IFERROR(AVERAGE(F14:CG14),"")
B15: 1.03 | C15: Técnico | D15: =IFERROR(E15/$E$51,"") | E15: =IFERROR(AVERAGE(F15:CG15),"")
B16: 1.04 | C16: Encarregado | D16: =IFERROR(E16/$E$51,"") -> 0.1476687 | E16: =IFERROR(AVERAGE(F16:CG16),"") -> 1 | F16: 1 | G16: 1 | H16: 1 | I16: 1 | J16: 1 | K16: 1 | L16: 1 | M16: 1 | N16: 1 | O16: 1 | P16: 1 | Q16: 1 | R16: 1 | S16: 1
B17: 1.05 | C17: Estagiário | D17: =IFERROR(E17/$E$51,"") | E17: =IFERROR(AVERAGE(F17:CG17),"")
B18: 1.06 | C18: Motorista veículos leves | D18: =IFERROR(E18/$E$51,"") | E18: =IFERROR(AVERAGE(F18:CG18),"")
B19: 2 | C19: DIRETA PREVISTA
B20: 2.01 | C20: Ajudante de pedreiro - servente | D20: =IFERROR(E20/$E$51,"") -> 0.27076591 | E20: =IFERROR(AVERAGE(F20:CG20),"") -> 1.8336039 | F20: 2.0795455 | G20: 1.1818182 | H20: 1 | I20: 2.6590909 | J20: 2.5113636 | K20: 3.25 | L20: 2.4886364 | M20: 1.6590909 | N20: 1 | O20: 1.2045455 | P20: 3.6477273 | Q20: 1.4886364 | R20: 1.0795455 | S20: 0.42045455
B21: 2.02 | C21: Pedreiro | D21: =IFERROR(E21/$E$51,"") -> 0.066882416 | E21: =IFERROR(AVERAGE(F21:CG21),"") -> 0.45292208 | F21: 0.10227273 | G21: 0 | H21: 0 | I21: 2.0681818 | J21: 1.3068182 | K21: 0.40909091 | L21: 0.18181818 | M21: 0.022727273 | N21: 0 | O21: 0.20454545 | P21: 1.2159091 | Q21: 0.38636364 | R21: 0.44318182 | S21: 0
B22: 2.03 | C22: Carpinteiro | D22: =IFERROR(E22/$E$51,"") -> 0.017259978 | E22: =IFERROR(AVERAGE(F22:CG22),"") -> 0.11688312 | F22: 0 | G22: 0.10227273 | H22: 0 | I22: 0.40909091 | J22: 0 | K22: 0.10227273 | L22: 0 | M22: 0 | N22: 0 | O22: 0 | P22: 0.27272727 | Q22: 0.34090909 | R22: 0.14772727 | S22: 0.26136364
B23: 2.04 | C23: Ajudante de carpinteiro | D23: =IFERROR(E23/$E$51,"") -> 0.012944984 | E23: =IFERROR(AVERAGE(F23:CG23),"") -> 0.087662338 | F23: 0 | G23: 0.10227273 | H23: 0 | I23: 0.40909091 | J23: 0 | K23: 0.10227273 | L23: 0 | M23: 0 | N23: 0 | O23: 0 | P23: 0.27272727 | Q23: 0.34090909 | R23: 0 | S23: 0
B24: 2.05 | C24: Ferreiro / armador | D24: =IFERROR(E24/$E$51,"") -> 0.0021574973 | E24: =IFERROR(AVERAGE(F24:CG24),"") -> 0.01461039 | F24: 0 | G24: 0.10227273 | H24: 0 | I24: 0.10227273 | J24: 0 | K24: 0 | L24: 0 | M24: 0 | N24: 0 | O24: 0 | P24: 0 | Q24: 0 | R24: 0 | S24: 0
B25: 2.06 | C25: Pedreiro azulejista | D25: =IFERROR(E25/$E$51,"") -> 0.010787487 | E25: =IFERROR(AVERAGE(F25:CG25),"") -> 0.073051948 | F25: 0 | G25: 0 | H25: 0 | I25: 0 | J25: 0 | K25: 0 | L25: 0.10227273 | M25: 0 | N25: 0 | O25: 0 | P25: 0.92045455 | Q25: 0 | R25: 0 | S25: 0
B26: 2.07 | C26: Ajudante de ferreiro / armador | D26: =IFERROR(E26/$E$51,"") -> 0.0021574973 | E26: =IFERROR(AVERAGE(F26:CG26),"") -> 0.01461039 | F26: 0 | G26: 0.10227273 | H26: 0 | I26: 0.10227273 | J26: 0 | K26: 0 | L26: 0 | M26: 0 | N26: 0 | O26: 0 | P26: 0 | Q26: 0 | R26: 0 | S26: 0
B27: 2.08 | C27: Pedreiro de massa - Betinho | D27: =IFERROR(E27/$E$51,"") -> 0.0399137 | E27: =IFERROR(AVERAGE(F27:CG27),"") -> 0.27029221 | F27: 0 | G27: 0 | H27: 0 | I27: 0 | J27: 0 | K27: 1.125 | L27: 1.4090909 | M27: 0.63636364 | N27: 0 | O27: 0 | P27: 0.51136364 | Q27: 0.10227273 | R27: 0 | S27: 0
B28: 2.09 | C28: Pintor | D28: =IFERROR(E28/$E$51,"") -> 0.090614887 | E28: =IFERROR(AVERAGE(F28:CG28),"") -> 0.61363636 | F28: 0 | G28: 0 | H28: 0 | I28: 0 | J28: 0 | K28: 0.30681818 | L28: 0.48863636 | M28: 1.5681818 | N28: 2 | O28: 2 | P28: 1.3863636 | Q28: 0.84090909 | R28: 0 | S28: 0
B29: 2.10 | C29: Ajudante de pintor | D29: =IFERROR(E29/$E$51,"") -> 0.086299892 | E29: =IFERROR(AVERAGE(F29:CG29),"") -> 0.58441558 | F29: 0 | G29: 0 | H29: 0 | I29: 0 | J29: 0 | K29: 0 | L29: 0.38636364 | M29: 1.5681818 | N29: 2 | O29: 2 | P29: 1.3863636 | Q29: 0.84090909 | R29: 0 | S29: 0
B30: 2.11 | C30: Eletricista - FP | D30: =IFERROR(E30/$E$51,"") -> 0.10895361 | E30: =IFERROR(AVERAGE(F30:CG30),"") -> 0.73782468 | F30: 0 | G30: 0 | H30: 0 | I30: 0 | J30: 0 | K30: 1.125 | L30: 1.3068182 | M30: 1.8181818 | N30: 2.125 | O30: 3.4659091 | P30: 0.48863636 | Q30: 0 | R30: 0 | S30: 0
B31: 2.12 | C31: Ajudante eletricista - FP | D31: =IFERROR(E31/$E$51,"") -> 0.11003236 | E31: =IFERROR(AVERAGE(F31:CG31),"") -> 0.74512987 | F31: 0 | G31: 0 | H31: 0 | I31: 0 | J31: 0 | K31: 1.125 | L31: 1.3068182 | M31: 1.8181818 | N31: 2.125 | O31: 3.6704545 | P31: 0.38636364 | Q31: 0 | R31: 0 | S31: 0
... B43: 2.24 | C43: Desmobilização | D43: =IFERROR(E43/$E$51,"") -> 0 | E43: =IFERROR(AVERAGE(F43:CG43),"") -> 0 | F43: 0 | G43: 0 | H43: 0 | I43: 0 | J43: 0 | K43: 0 | L43: 0 | M43: 0 | N43: 0 | O43: 0 | P43: 0 | Q43: 0 | R43: 0 | S43: 0
B44: 2.25 | D44: =IFERROR(E44/$E$51,"") | E44: =IFERROR(AVERAGE(F44:CG44),"")
B45: 2.26 | D45: =IFERROR(E45/$E$51,"") | E45: =IFERROR(AVERAGE(F45:CG45),"")
B46: 2.27 | D46: =IFERROR(E46/$E$51,"") | E46: =IFERROR(AVERAGE(F46:CG46),"")
B47: 2.28 | D47: =IFERROR(E47/$E$51,"") | E47: =IFERROR(AVERAGE(F47:CG47),"")
B48: 2.29 | D48: =IFERROR(E48/$E$51,"") | E48: =IFERROR(AVERAGE(F48:CG48),"")
B49: 2.30 | D49: =IFERROR(E49/$E$51,"") | E49: =IFERROR(AVERAGE(F49:CG49),"")
B50: TOTAL: | C50: MO INDIRETA | D50: =IFERROR(E50/$E$52,"") -> 0.73524804 | E50: =AVERAGE(F50:CG50) -> 1 | F50: =IF(SUM(F13:F18)=0,"",SUM(F13:F18)) -> 1 | G50: =IF(SUM(G13:G18)=0,"",SUM(G13:G18)) -> 1 | H50: =IF(SUM(H13:H18)=0,"",SUM(H13:H18)) -> 1 | I50: =IF(SUM(I13:I18)=0,"",SUM(I13:I18)) -> 1 | J50: =IF(SUM(J13:J18)=0,"",SUM(J13:J18)) -> 1 | K50: =IF(SUM(K13:K18)=0,"",SUM(K13:K18)) -> 1 | L50: =IF(SUM(L13:L18)=0,"",SUM(L13:L18)) -> 1 | M50: =IF(SUM(M13:M18)=0,"",SUM(M13:M18)) -> 1 | ... CG50: =IF(SUM(CG13:CG18)=0,"",SUM(CG13:CG18))
B51: TOTAL: | C51: MO DIRETA | D51: =IFERROR(E51/$E$52,"") -> 4.9790377 | E51: =AVERAGE(F51:CG51) -> 6.7719156 | F51: =IF(SUM(F20:F49)=0,"",SUM(F20:F49)) -> 2.1818182 | G51: =IF(SUM(G20:G49)=0,"",SUM(G20:G49)) -> 1.5909091 | H51: =IF(SUM(H20:H49)=0,"",SUM(H20:H49)) -> 1 | I51: =IF(SUM(I20:I49)=0,"",SUM(I20:I49)) -> 5.75 | J51: =IF(SUM(J20:J49)=0,"",SUM(J20:J49)) -> 10.034091 | K51: =IF(SUM(K20:K49)=0,"",SUM(K20:K49)) -> 12.068182 | L51: =IF(SUM(L20:L49)=0,"",SUM(L20:L49)) -> 8.0795455 | M51: =IF(SUM(M20:M49)=0,"",SUM(M20:M49)) -> 9.9090909 | ... CG51: =IF(SUM(CG20:CG49)=0,"",SUM(CG20:CG49))
B52: TOTAL: | C52: TOTAL PREVISTA | D52: =SUM(D50:D51) -> 5.7142857 | E52: =AVERAGE(F52:CG52) -> 1.3600852 | F52: =SUM(F50:F51) -> 3.1818182 | G52: =SUM(G50:G51) -> 2.5909091 | H52: =SUM(H50:H51) -> 2 | I52: =SUM(I50:I51) -> 6.75 | J52: =SUM(J50:J51) -> 11.034091 | K52: =SUM(K50:K51) -> 13.068182 | L52: =SUM(L50:L51) -> 9.0795455 | M52: =SUM(M50:M51) -> 10.909091 | ... CG52: =SUM(CG50:CG51) -> 0
E53: 20 | F53: =F51/$E$53 -> 0.10909091 | G53: =G51/$E$53 -> 0.079545455 | H53: =H51/$E$53 -> 0.05 | I53: =I51/$E$53 -> 0.2875 | J53: =J51/$E$53 -> 0.50170455 | K53: =K51/$E$53 -> 0.60340909 | L53: =L51/$E$53 -> 0.40397727 | M53: =M51/$E$53 -> 0.49545455 | ... CG53: =CG51/$E$53 -> #VALUE!
B62: ITEM | C62: DESCRIÇÃO | E62: MÊS | F62: 1 | J62: 2 | N62: 3 | R62: 4 | V62: 5 | Z62: 6 | AD62: 7 | AH62: 8 | AL62: 9 | AP62: 10 | AT62: 11 | AX62: 12 | BB62: 13 | BF62: 14 | BJ62: 15 | BN62: 16 | BR62: 17 | BV62: 18 | BZ62: 19 | CD62: 19
E63: Semana | F63: 1 | G63: 2 | H63: 3 | I63: 4 | J63: 5 | K63: 6 | L63: 7 | M63: 8 | N63: 9 | O63: 10 | P63: 11 | Q63: 12 | R63: 13 | S63: 14 | T63: 15 | U63: 16 | V63: 17 | W63: 18 | X63: 19 | Y63: 20 | Z63: 21 | AA63: 22 | AB63: 23 | AC63: 24 | AD63: 25 | AE63: 26 | AF63: 27 | AG63: 28 | AH63: 29 | AI63: 30 | AJ63: 31 | AK63: 32 | AL63: 33 | AM63: 34 | AN63: 35 | AO63: 36 | AP63: 37 | AQ63: 38 | AR63: 39 | AS63: 40 | AT63: 41 | AU63: 42 | AV63: 43 | AW63: 44 | AX63: 45 | AY63: 46 | AZ63: 47 | BA63: 48 | BB63: 49 | BC63: 50 | BD63: 51 | BE63: 52 | BF63: 53 | BG63: 54 | BH63: 55 | BI63: 56 | BJ63: 57 | BK63: 58 | BL63: 59 | BM63: 60 | BN63: 61 | BO63: 62 | BP63: 63 | BQ63: 64 | BR63: 65 | BS63: 66 | BT63: 67 | BU63: 68 | BV63: 69 | BW63: 70 | BX63: 71 | BY63: 72 | BZ63: 73 | CA63: 74 | CB63: 75 | CC63: 76 | CD63: 77 | CE63: 78 | CF63: 78 | CG63: 78
B64: 1 | C64: INDIRETA REAL | F64: =AVERAGE(F105:I105) -> 0 | J64: =AVERAGE(J105:M105) -> 0 | N64: =AVERAGE(N105:Q105) -> #DIV/0! | R64: =AVERAGE(R105:U105) -> #DIV/0! | V64: =AVERAGE(V105:Y105) -> #DIV/0! | Z64: =AVERAGE(Z105:AC105) -> #DIV/0! | AD64: =AVERAGE(AD105:AG105) -> #DIV/0! | AH64: =AVERAGE(AH105:AK105) -> #DIV/0! | AL64: =AVERAGE(AL105:AO105) -> #DIV/0! | AP64: =AVERAGE(AP105:AS105) -> #DIV/0! | AT64: =AVERAGE(AT105:AW105) -> #DIV/0! | AX64: =AVERAGE(AX105:BA105) -> #DIV/0! | BB64: =AVERAGE(BB105:BE105) -> #DIV/0! | BF64: =AVERAGE(BF105:BI105) -> #DIV/0! | BJ64: =AVERAGE(BJ105:BM105) -> #DIV/0! | BN64: =AVERAGE(BN105:BQ105) -> #DIV/0! | BR64: =AVERAGE(BR105:BU105) -> #DIV/0! | BV64: =AVERAGE(BV105:BY105) -> #DIV/0! | BZ64: =AVERAGE(BZ105:CC105) -> #DIV/0! | CD64: =AVERAGE(CD105:CG105) -> #DIV/0!
...

Sheet PMO REAL
B2: PERMANENCIA DE MÃO DE OBRA
B3: Julio Ferraz Projetos e Obras
B4: ANEXO "C"
C5: Cliente: RICARDO HABER
C6: Obra: HOTEL CAMPANÁRIO
C7: Local: APARECIDA - SP
B11: ITEM | C11: DESCRIÇÃO | E11: SEMANA | F11: 0 | K11: =F11+1 -> 1 | R11: =K11+1 -> 2 | Y11: =R11+1 -> 3 | AF11: =Y11+1 -> 4 | AM11: =AF11+1 -> 5 | AT11: =AM11+1 -> 6 | BA11: =AT11+1 -> 7 | BH11: =BA11+1 -> 8 | BO11: =BH11+1 -> 9 | BV11: =BO11+1 -> 10 | CC11: =BV11+1 -> 11 | CJ11: =CC11+1 -> 12 | CQ11: =CJ11+1 -> 13 | CX11: =CQ11+1 -> 14 | DE11: =CX11+1 -> 15 | DL11: =DE11+1 -> 16 | DS11: =DL11+1 -> 17 | DZ11: =DS11+1 -> 18 | EG11: =DZ11+1 -> 19 | EN11: =EG11+1 -> 20 | EU11: =EN11+1 -> 21 | FB11: =EU11+1 -> 22 | FI11: =FB11+1 -> 23 | FP11: =FI11+1 -> 24 | FW11: =FP11+1 -> 25 | GD11: =FW11+1 -> 26 | GK11: =GD11+1 -> 27 | GR11: =GK11+1 -> 28 | GY11: =GR11+1 -> 29 | HF11: =GY11+1 -> 30 | HM11: =HF11+1 -> 31 | HT11: =HM11+1 -> 32 | IA11: =HT11+1 -> 33 | IH11: =IA11+1 -> 34 | IO11: =IH11+1 -> 35 | IV11: =IO11+1 -> 36 | JC11: =IV11+1 -> 37 | JJ11: =JC11+1 -> 38 | JQ11: =JJ11+1 -> 39 | JX11: =JQ11+1 -> 40 | KE11: =JX11+1 -> 41 | KL11: =KE11+1 -> 42 | KS11: =KL11+1 -> 43 | KZ11: =KS11+1 -> 44 | LG11: =KZ11+1 -> 45 | LN11: =LG11+1 -> 46 | LU11: =LN11+1 -> 47 | MB11: =LU11+1 -> 48 | MI11: =MB11+1 -> 49 | MP11: =MI11+1 -> 50 | MW11: =MP11+1 -> 51 | ND11: =MW11+1 -> 52 | NK11: =ND11+1 -> 53 | NR11: =NK11+1 -> 54 | NY11: =NR11+1 -> 55 | OF11: =NY11+1 -> 56 | OM11: =OF11+1 -> 57 | OT11: =OM11+1 -> 58 | PA11: =OT11+1 -> 59 | PH11: =PA11+1 -> 60 | PO11: =PH11+1 -> 61 | PV11: =PO11+1 -> 62 | QC11: =PV11+1 -> 63 | QJ11: =QC11+1 -> 64 | QQ11: =QJ11+1 -> 65 | QX11: =QQ11+1 -> 66 | RE11: =QX11+1 -> 67 | RL11: =RE11+1 -> 68 | RS11: =RL11+1 -> 69 | RZ11: =RS11+1 -> 70 | SG11: =RZ11+1 -> 71 | SN11: =SG11+1 -> 72 | SU11: =SN11+1 -> 73 | TB11: =SU11+1 -> 74 | TI11: =TB11+1 -> 75 | TP11: =TI11+1 -> 76 | TW11: =TP11+1 -> 77 | UD11: =TW11+1 -> 78 | UK11: =UD11+1 -> 79
F12: =F11 -> 0 | G12: =IF(G13="seg",OFFSET(G12,0,-1)+1,OFFSET(G12,0,-1)) -> 0 | H12: =IF(H13="seg",OFFSET(H12,0,-1)+1,OFFSET(H12,0,-1)) -> 0 | I12: =IF(I13="seg",OFFSET(I12,0,-1)+1,OFFSET(I12,0,-1)) -> 0 | J12: =IF(J13="seg",OFFSET(J12,0,-1)+1,OFFSET(J12,0,-1)) -> 0 | K12: =IF(K13="seg",OFFSET(K12,0,-1)+1,OFFSET(K12,0,-1)) -> 1 | L12: =IF(L13="seg",OFFSET(L12,0,-1)+1,OFFSET(L12,0,-1)) -> 1 | M12: =IF(M13="seg",OFFSET(M12,0,-1)+1,OFFSET(M12,0,-1)) -> 1 | N12: =IF(N13="seg",OFFSET(N12,0,-1)+1,OFFSET(N12,0,-1)) -> 1 | ... US12: =IF(US13="seg",OFFSET(US12,0,-1)+1,OFFSET(US12,0,-1)) -> 80
E13: Dia | F13: =TEXT(F14,"ddd") -> qua | G13: =TEXT(G14,"ddd") -> qui | H13: =TEXT(H14,"ddd") -> sex | I13: =TEXT(I14,"ddd") -> sáb | J13: =TEXT(J14,"ddd") -> dom | K13: =TEXT(K14,"ddd") -> seg | L13: =TEXT(L14,"ddd") -> ter | M13: =TEXT(M14,"ddd") -> qua | ... US13: =TEXT(US14,"ddd") -> ter
F14: 45196 | G14: =OFFSET(G14,0,-1)+1 -> 45197 | H14: =OFFSET(H14,0,-1)+1 -> 45198 | I14: =OFFSET(I14,0,-1)+1 -> 45199 | J14: =OFFSET(J14,0,-1)+1 -> 45200 | K14: =OFFSET(K14,0,-1)+1 -> 45201 | L14: =OFFSET(L14,0,-1)+1 -> 45202 | M14: =OFFSET(M14,0,-1)+1 -> 45203 | N14: =OFFSET(N14,0,-1)+1 -> 45204 | ... US14: =OFFSET(US14,0,-1)+1 -> 45755
B15: 1 | C15: INDIRETA | F15: =AVERAGE(F56:J56) -> #DIV/0! | K15: =AVERAGE(K56:Q56) -> #DIV/0! | R15: =AVERAGE(R56:X56) -> #DIV/0! | Y15: =AVERAGE(Y56:AE56) -> #DIV/0! | AF15: =AVERAGE(AF56:AL56) -> #DIV/0! | AM15: =AVERAGE(AM56:AS56) -> #DIV/0! | AT15: =AVERAGE(AT56:AZ56) -> #DIV/0! | BA15: =AVERAGE(BA56:BG56) -> #DIV/0! | BH15: =AVERAGE(BH56:BN56) -> #DIV/0! | BO15: =AVERAGE(BO56:BU56) -> #DIV/0! | BV15: =AVERAGE(BV56:CB56) -> #DIV/0! | CC15: =AVERAGE(CC56:CI56) -> #DIV/0! | CJ15: =AVERAGE(CJ56:CP56) -> #DIV/0! | CQ15: =AVERAGE(CQ56:CW56) -> #DIV/0! | CX15: =AVERAGE(CX56:DD56) -> #DIV/0! | DE15: =AVERAGE(DE56:DK56) -> #DIV/0! | DL15: =AVERAGE(DL56:DR56) -> #DIV/0! | DS15: =AVERAGE(DS56:DY56) -> #DIV/0! | DZ15: =AVERAGE(DZ56:EF56) -> #DIV/0! | EG15: =AVERAGE(EG56:EM56) -> #DIV/0! | EN15: =AVERAGE(EN56:ET56) -> #DIV/0! | EU15: =AVERAGE(EU56:FA56) -> #DIV/0! | FB15: =AVERAGE(FB56:FH56) -> #DIV/0! | FI15: =AVERAGE(FI56:FO56) -> #DIV/0! | FP15: =AVERAGE(FP56:FV56) -> #DIV/0! | FW15: =AVERAGE(FW56:GC56) -> #DIV/0! | GD15: =AVERAGE(GD56:GJ56) -> #DIV/0! | GK15: =AVERAGE(GK56:GQ56) -> #DIV/0! | GR15: =AVERAGE(GR56:GX56) -> #DIV/0! | GY15: =AVERAGE(GY56:HE56) -> #DIV/0! | HF15: =AVERAGE(HF56:HL56) -> #DIV/0! | HM15: =AVERAGE(HM56:HS56) -> #DIV/0! | HT15: =AVERAGE(HT56:HZ56) -> #DIV/0! | IA15: =AVERAGE(IA56:IG56) -> #DIV/0! | IH15: =AVERAGE(IH56:IN56) -> #DIV/0! | IO15: =AVERAGE(IO56:IU56) -> #DIV/0! | IV15: =AVERAGE(IV56:JB56) -> #DIV/0! | JC15: =AVERAGE(JC56:JI56) -> #DIV/0! | JJ15: =AVERAGE(JJ56:JP56) -> #DIV/0! | JQ15: =AVERAGE(JQ56:JW56) -> #DIV/0! | JX15: =AVERAGE(JX56:KD56) -> #DIV/0! | KE15: =AVERAGE(KE56:KK56) -> #DIV/0! | KL15: =AVERAGE(KL56:KR56) -> #DIV/0! | KS15: =AVERAGE(KS56:KY56) -> #DIV/0! | KZ15: =AVERAGE(KZ56:LF56) -> #DIV/0! | LG15: =AVERAGE(LG56:LM56) -> #DIV/0! | LN15: =AVERAGE(LN56:LT56) -> #DIV/0! | LU15: =AVERAGE(LU56:MA56) -> #DIV/0! | MB15: =AVERAGE(MB56:MH56) -> #DIV/0! | MI15: =AVERAGE(MI56:MO56) -> #DIV/0! | MP15: =AVERAGE(MP56:MV56) -> #DIV/0! | MW15: =AVERAGE(MW56:NC56) -> #DIV/0! | ND15: =AVERAGE(ND56:NJ56) -> #DIV/0! | NK15: =AVERAGE(NK56:NQ56) -> #DIV/0! | NR15: =AVERAGE(NR56:NX56) -> #DIV/0! | NY15: =AVERAGE(NY56:OE56) -> #DIV/0! | OF15: =AVERAGE(OF56:OL56) -> #DIV/0! | OM15: =AVERAGE(OM56:OS56) -> #DIV/0! | OT15: =AVERAGE(OT56:OZ56) -> #DIV/0! | PA15: =AVERAGE(PA56:PG56) -> #DIV/0! | PH15: =AVERAGE(PH56:PN56) -> #DIV/0! | PO15: =AVERAGE(PO56:PU56) -> #DIV/0! | PV15: =AVERAGE(PV56:QB56) -> #DIV/0! | QC15: =AVERAGE(QC56:QI56) -> #DIV/0! | QJ15: =AVERAGE(QJ56:QP56) -> #DIV/0! | QQ15: =AVERAGE(QQ56:QW56) -> #DIV/0! | QX15: =AVERAGE(QX56:RD56) -> #DIV/0! | RE15: =AVERAGE(RE56:RK56) -> #DIV/0! | RL15: =AVERAGE(RL56:RR56) -> #DIV/0! | RS15: =AVERAGE(RS56:RY56) -> #DIV/0! | RZ15: =AVERAGE(RZ56:SF56) -> #DIV/0! | SG15: =AVERAGE(SG56:SM56) -> #DIV/0! | SN15: =AVERAGE(SN56:ST56) -> #DIV/0! | SU15: =AVERAGE(SU56:TA56) -> #DIV/0! | TB15: =AVERAGE(TB56:TH56) -> #DIV/0! | TI15: =AVERAGE(TI56:TO56) -> #DIV/0! | TP15: =AVERAGE(TP56:TV56) -> #DIV/0! | TW15: =AVERAGE(TW56:UC56) -> #DIV/0! | UD15: =AVERAGE(UD56:UJ56) -> #DIV/0! | UK15: =AVERAGE(UK56:UQ56) -> #DIV/0! | UR15: =AVERAGE(UR56:UX56) -> #DIV/0!
B16: 1.01 | C16: Engenheiro | D16: =IFERROR(E16/$E$55,"") | E16: =IFERROR(AVERAGE(F16:UU16),"")
B17: 1.02 | C17: Técnico de Segurança do Trabalho | D17: =IFERROR(E17/$E$55,"") | E17: =IFERROR(AVERAGE(F17:US17),"")
B18: 1.03 | C18: Técnico | D18: =IFERROR(E18/$E$55,"") | E18: =IFERROR(AVERAGE(F18:US18),"")
B19: 1.04 | C19: Encarregado | D19: =IFERROR(E19/$E$55,"") | E19: =IFERROR(AVERAGE(F19:US19),"")
B20: 1.05 | C20: Estagiário | D20: =IFERROR(E20/$E$55,"") | E20: =IFERROR(AVERAGE(F20:US20),"")
B21: 1.06 | C21: Motorista veículos leves | D21: =IFERROR(E21/$E$55,"") | E21: =IFERROR(AVERAGE(F21:US21),"")
B22: 2 | C22: DIRETA
B23: 2.01 | C23: Ajudante de pedreiro - servente | D23: =IFERROR(E23/$E$55,"") | E23: =IFERROR(AVERAGE(F23:US23),"")
B24: 2.02 | C24: Pedreiro | D24: =IFERROR(E24/$E$55,"") | E24: =IFERROR(AVERAGE(F24:US24),"")
B25: 2.03 | C25: Carpinteiro | D25: =IFERROR(E25/$E$55,"") | E25: =IFERROR(AVERAGE(F25:US25),"")
B26: 2.04 | C26: Ajudante de carpinteiro | D26: =IFERROR(E26/$E$55,"") | E26: =IFERROR(AVERAGE(F26:US26),"")
B27: 2.05 | C27: Ferreiro / armador | D27: =IFERROR(E27/$E$55,"") | E27: =IFERROR(AVERAGE(F27:US27),"")
B28: 2.06 | C28: Pedreiro azulejista | D28: =IFERROR(E28/$E$55,"") | E28: =IFERROR(AVERAGE(F28:US28),"")
B29: 2.07 | C29: Ajudante de ferreiro / armador | D29: =IFERROR(E29/$E$55,"") | E29: =IFERROR(AVERAGE(F29:US29),"")
B30: 2.08 | C30: Pedreiro de massa - Betinho | D30: =IFERROR(E30/$E$55,"") | E30: =IFERROR(AVERAGE(F30:US30),"")
B31: 2.09 | C31: Pintor | D31: =IFERROR(E31/$E$55,"") | E31: =IFERROR(AVERAGE(F31:US31),"")
B32: 2.10 | C32: Ajudante de pintor | D32: =IFERROR(E32/$E$55,"") | E32: =IFERROR(AVERAGE(F32:US32),"")
B33: 2.11 | C33: Eletricista - FP | D33: =IFERROR(E33/$E$55,"") | E33: =IFERROR(AVERAGE(F33:US33),"")
B34: 2.12 | C34: Ajudante eletricista - FP | D34: =IFERROR(E34/$E$55,"") | E34: =IFERROR(AVERAGE(F34:US34),"")
... B46: 2.24 | C46: Desmobilização | D46: =IFERROR(E46/$E$55,"") | E46: =IFERROR(AVERAGE(F46:US46),"")
B47: 2.25 | D47: =IFERROR(E47/$E$55,"") | E47: =IFERROR(AVERAGE(F47:US47),"")
B48: 2.26
B49: 2.27 | D49: =IFERROR(E49/$E$55,"") | E49: =IFERROR(AVERAGE(F49:US49),"")
B50: 2.28 | D50: =IFERROR(E50/$E$55,"") | E50: =IFERROR(AVERAGE(F50:US50),"")
B51: 2.29 | D51: =IFERROR(E51/$E$55,"") | E51: =IFERROR(AVERAGE(F51:US51),"")
B52: 2.30 | D52: =IFERROR(E52/$E$55,"") | E52: =IFERROR(AVERAGE(F52:US52),"")
B53: 2.31 | D53: =IFERROR(E53/$E$55,"") | E53: =IFERROR(AVERAGE(F53:US53),"")
B54: TOTAL: | C54: MO INDIRETA | D54: =IFERROR(E54/$E$56,"") | E54: =AVERAGE(F54:US54) -> #DIV/0! | F54: =IF(SUM(F16:F21)=0,"",SUM(F16:F21)) | G54: =IF(SUM(G16:G21)=0,"",SUM(G16:G21)) | H54: =IF(SUM(H16:H21)=0,"",SUM(H16:H21)) | I54: =IF(SUM(I16:I21)=0,"",SUM(I16:I21)) | J54: =IF(SUM(J16:J21)=0,"",SUM(J16:J21)) | K54: =IF(SUM(K16:K21)=0,"",SUM(K16:K21)) | L54: =IF(SUM(L16:L21)=0,"",SUM(L16:L21)) | M54: =IF(SUM(M16:M21)=0,"",SUM(M16:M21)) | ... US54: =IF(SUM(US16:US21)=0,"",SUM(US16:US21))
B55: TOTAL: | C55: MO DIRETA | D55: =IFERROR(E55/$E$56,"") | E55: =AVERAGE(F55:US55) -> #DIV/0! | F55: =IF(SUM(F23:F53)=0,"",SUM(F23:F53)) | G55: =IF(SUM(G23:G53)=0,"",SUM(G23:G53)) | H55: =IF(SUM(H23:H53)=0,"",SUM(H23:H53)) | I55: =IF(SUM(I23:I53)=0,"",SUM(I23:I53)) | J55: =IF(SUM(J23:J53)=0,"",SUM(J23:J53)) | K55: =IF(SUM(K23:K53)=0,"",SUM(K23:K53)) | L55: =IF(SUM(L23:L53)=0,"",SUM(L23:L53)) | M55: =IF(SUM(M23:M53)=0,"",SUM(M23:M53)) | ... US55: =IF(SUM(US23:US53)=0,"",SUM(US23:US53))
...
